Workbook

Sheet Underwriting Dashboard
B2: AUTO LOAN UNDERWRITING MODEL
B4: Consumer Credit Risk Assessment | Quanthaven Labs LLC
B6: ▸ BORROWER INPUTS | E6: ▸ CALCULATED RISK METRICS
B7: Credit Score | C7: 720 | E7: Loan Amount | F7: =C10-C11 -> 40000
B8: Annual Gross Income | C8: 72000 | E8: Monthly Interest Rate | F8: =C13/12 -> 0.0062416667
B9: Monthly Non-Auto Debt Payments | C9: 450 | E9: Est. Monthly Payment | F9: =IFERROR(PMT(F8,C12,-F7),0) -> 801.32788
B10: Vehicle Purchase Price | C10: 40000 | E10: Back-End DTI (incl. auto) | F10: =(C9+F9)/(C8/12) -> 0.20855465
B11: Down Payment | C11: 0 | E11: Loan-to-Value (LTV) | F11: =IFERROR(F7/C10,0) -> 1
B12: Loan Term (Months) | C12: 60 | E12: Credit Tier | F12: =IF(C7>=750,"Super-Prime",IF(C7>=700,"Prime",IF(C7>=650,"Near-Prime","Sub-Prime"))) -> Prime
B13: Annual Interest Rate (APR) | C13: 0.0749 | E13: Negative Equity at Funding? | F13: =IF(F11>1,"Yes — LTV exceeds 100%","No") -> No
B15: ▸ LENDER POLICY THRESHOLDS (editable) | E15: ▸ APPROVAL SCORECARD
B16: Max Back-End DTI | C16: 0.45 | E16: Credit Score Check | F16: =IF(C7>=C18,"✔ PASS","✘ FAIL") -> ✔ PASS
B17: Max LTV at Origination | C17: 1.1 | E17: DTI Check | F17: =IF(F10<=C16,"✔ PASS","✘ FAIL") -> ✔ PASS
B18: Min Credit Score | C18: 620 | E18: LTV Check | F18: =IF(F11<=C17,"✔ PASS","✘ FAIL") -> ✔ PASS
B19: Max Loan Term (Months) | C19: 72 | E19: Loan Term Check | F19: =IF(C12<=C19,"✔ PASS","✘ FAIL") -> ✔ PASS
B21: ▸ NOTES (blue = input | black = formula) | E21: ▸ OVERALL APPROVAL LIKELIHOOD
E22: =IF(AND(F16="✔ PASS",F17="✔ PASS",F18="✔ PASS",F19="✔ PASS"),"LIKELY APPROVED",IF(COUNTIF(F16:F19,"✘ FAIL")=1,"CONDITIONAL — REVIEW REQUIRED","LIKELY DECLINED")) -> LIKELY APPROVED

Sheet Amortization Schedule
B2: LOAN AMORTIZATION SCHEDULE
B4: Driven by Underwriting Dashboard inputs | Quanthaven Labs LLC
B6: Loan Amount | C6: Monthly Payment | D6: Total Interest | E6: Total Cost | F6: APR | G6: Term
B7: ='Underwriting Dashboard'!F7 -> 40000 | C7: ='Underwriting Dashboard'!F9 -> 801.32788 | D7: =IF(B7>0,C7*'Underwriting Dashboard'!C12-B7,0) -> 8079.6727 | E7: =C7*'Underwriting Dashboard'!C12 -> 48079.673 | F7: ='Underwriting Dashboard'!C13 -> 0.0749 | G7: ='Underwriting Dashboard'!C12&" mo" -> 60 mo
B9: # | C9: Payment Date | D9: Beginning Balance | E9: Payment | F9: Principal | G9: Interest | H9: Ending Balance
B10: =IF(1<='Underwriting Dashboard'!C12,1,"") -> 1 | C10: =IF(B10<>"",DATE(YEAR(TODAY()),MONTH(TODAY())+1,1),"") -> 46113 | D10: =IF(B10<>"",'Underwriting Dashboard'!F7,"") -> 40000 | E10: =IF(B10<>"",'Underwriting Dashboard'!F9,"") -> 801.32788 | F10: =IF(B10<>"",PPMT('Underwriting Dashboard'!F8,1,'Underwriting Dashboard'!C12,-'Underwriting Dashboard'!F7),"") -> 551.66121 | G10: =IF(B10<>"",IPMT('Underwriting Dashboard'!F8,1,'Underwriting Dashboard'!C12,-'Underwriting Dashboard'!F7),"") -> 249.66667 | H10: =IF(B10<>"",D10-F10,"") -> 39448.339
B11: =IF(2<='Underwriting Dashboard'!C12,2,"") -> 2 | C11: =IF(B11<>"",EDATE(C10,1),"") -> 46143 | D11: =IF(B11<>"",G10,"") -> 249.66667 | E11: =IF(B11<>"",'Underwriting Dashboard'!F9,"") -> 801.32788 | F11: =IF(B11<>"",PPMT('Underwriting Dashboard'!F8,2,'Underwriting Dashboard'!C12,-'Underwriting Dashboard'!F7),"") -> 555.1045 | G11: =IF(B11<>"",IPMT('Underwriting Dashboard'!F8,2,'Underwriting Dashboard'!C12,-'Underwriting Dashboard'!F7),"") -> 246.22338 | H11: =IF(B11<>"",D11-F11,"") -> -305.43783
B12: =IF(3<='Underwriting Dashboard'!C12,3,"") -> 3 | C12: =IF(B12<>"",EDATE(C11,1),"") -> 46174 | D12: =IF(B12<>"",G11,"") -> 246.22338 | E12: =IF(B12<>"",'Underwriting Dashboard'!F9,"") -> 801.32788 | F12: =IF(B12<>"",PPMT('Underwriting Dashboard'!F8,3,'Underwriting Dashboard'!C12,-'Underwriting Dashboard'!F7),"") -> 558.56927 | G12: =IF(B12<>"",IPMT('Underwriting Dashboard'!F8,3,'Underwriting Dashboard'!C12,-'Underwriting Dashboard'!F7),"") -> 242.7586 | H12: =IF(B12<>"",D12-F12,"") -> -312.34589
B13: =IF(4<='Underwriting Dashboard'!C12,4,"") -> 4 | C13: =IF(B13<>"",EDATE(C12,1),"") -> 46204 | D13: =IF(B13<>"",G12,"") -> 242.7586 | E13: =IF(B13<>"",'Underwriting Dashboard'!F9,"") -> 801.32788 | F13: =IF(B13<>"",PPMT('Underwriting Dashboard'!F8,4,'Underwriting Dashboard'!C12,-'Underwriting Dashboard'!F7),"") -> 562.05568 | G13: =IF(B13<>"",IPMT('Underwriting Dashboard'!F8,4,'Underwriting Dashboard'!C12,-'Underwriting Dashboard'!F7),"") -> 239.2722 | H13: =IF(B13<>"",D13-F13,"") -> -319.29707
B14: =IF(5<='Underwriting Dashboard'!C12,5,"") -> 5 | C14: =IF(B14<>"",EDATE(C13,1),"") -> 46235 | D14: =IF(B14<>"",G13,"") -> 239.2722 | E14: =IF(B14<>"",'Underwriting Dashboard'!F9,"") -> 801.32788 | F14: =IF(B14<>"",PPMT('Underwriting Dashboard'!F8,5,'Underwriting Dashboard'!C12,-'Underwriting Dashboard'!F7),"") -> 565.56384 | G14: =IF(B14<>"",IPMT('Underwriting Dashboard'!F8,5,'Underwriting Dashboard'!C12,-'Underwriting Dashboard'!F7),"") -> 235.76404 | H14: =IF(B14<>"",D14-F14,"") -> -326.29164
B15: =IF(6<='Underwriting Dashboard'!C12,6,"") -> 6 | C15: =IF(B15<>"",EDATE(C14,1),"") -> 46266 | D15: =IF(B15<>"",G14,"") -> 235.76404 | E15: =IF(B15<>"",'Underwriting Dashboard'!F9,"") -> 801.32788 | F15: =IF(B15<>"",PPMT('Underwriting Dashboard'!F8,6,'Underwriting Dashboard'!C12,-'Underwriting Dashboard'!F7),"") -> 569.0939 | G15: =IF(B15<>"",IPMT('Underwriting Dashboard'!F8,6,'Underwriting Dashboard'!C12,-'Underwriting Dashboard'!F7),"") -> 232.23398 | H15: =IF(B15<>"",D15-F15,"") -> -333.32987
B16: =IF(7<='Underwriting Dashboard'!C12,7,"") -> 7 | C16: =IF(B16<>"",EDATE(C15,1),"") -> 46296 | D16: =IF(B16<>"",G15,"") -> 232.23398 | E16: =IF(B16<>"",'Underwriting Dashboard'!F9,"") -> 801.32788 | F16: =IF(B16<>"",PPMT('Underwriting Dashboard'!F8,7,'Underwriting Dashboard'!C12,-'Underwriting Dashboard'!F7),"") -> 572.646 | G16: =IF(B16<>"",IPMT('Underwriting Dashboard'!F8,7,'Underwriting Dashboard'!C12,-'Underwriting Dashboard'!F7),"") -> 228.68188 | H16: =IF(B16<>"",D16-F16,"") -> -340.41202
B17: =IF(8<='Underwriting Dashboard'!C12,8,"") -> 8 | C17: =IF(B17<>"",EDATE(C16,1),"") -> 46327 | D17: =IF(B17<>"",G16,"") -> 228.68188 | E17: =IF(B17<>"",'Underwriting Dashboard'!F9,"") -> 801.32788 | F17: =IF(B17<>"",PPMT('Underwriting Dashboard'!F8,8,'Underwriting Dashboard'!C12,-'Underwriting Dashboard'!F7),"") -> 576.22026 | G17: =IF(B17<>"",IPMT('Underwriting Dashboard'!F8,8,'Underwriting Dashboard'!C12,-'Underwriting Dashboard'!F7),"") -> 225.10762 | H17: =IF(B17<>"",D17-F17,"") -> -347.53838
B18: =IF(9<='Underwriting Dashboard'!C12,9,"") -> 9 | C18: =IF(B18<>"",EDATE(C17,1),"") -> 46357 | D18: =IF(B18<>"",G17,"") -> 225.10762 | E18: =IF(B18<>"",'Underwriting Dashboard'!F9,"") -> 801.32788 | F18: =IF(B18<>"",PPMT('Underwriting Dashboard'!F8,9,'Underwriting Dashboard'!C12,-'Underwriting Dashboard'!F7),"") -> 579.81684 | G18: =IF(B18<>"",IPMT('Underwriting Dashboard'!F8,9,'Underwriting Dashboard'!C12,-'Underwriting Dashboard'!F7),"") -> 221.51104 | H18: =IF(B18<>"",D18-F18,"") -> -354.70922
B19: =IF(10<='Underwriting Dashboard'!C12,10,"") -> 10 | C19: =IF(B19<>"",EDATE(C18,1),"") -> 46388 | D19: =IF(B19<>"",G18,"") -> 221.51104 | E19: =IF(B19<>"",'Underwriting Dashboard'!F9,"") -> 801.32788 | F19: =IF(B19<>"",PPMT('Underwriting Dashboard'!F8,10,'Underwriting Dashboard'!C12,-'Underwriting Dashboard'!F7),"") -> 583.43586 | G19: =IF(B19<>"",IPMT('Underwriting Dashboard'!F8,10,'Underwriting Dashboard'!C12,-'Underwriting Dashboard'!F7),"") -> 217.89202 | H19: =IF(B19<>"",D19-F19,"") -> -361.92482
B20: =IF(11<='Underwriting Dashboard'!C12,11,"") -> 11 | C20: =IF(B20<>"",EDATE(C19,1),"") -> 46419 | D20: =IF(B20<>"",G19,"") -> 217.89202 | E20: =IF(B20<>"",'Underwriting Dashboard'!F9,"") -> 801.32788 | F20: =IF(B20<>"",PPMT('Underwriting Dashboard'!F8,11,'Underwriting Dashboard'!C12,-'Underwriting Dashboard'!F7),"") -> 587.07747 | G20: =IF(B20<>"",IPMT('Underwriting Dashboard'!F8,11,'Underwriting Dashboard'!C12,-'Underwriting Dashboard'!F7),"") -> 214.25041 | H20: =IF(B20<>"",D20-F20,"") -> -369.18546
B21: =IF(12<='Underwriting Dashboard'!C12,12,"") -> 12 | C21: =IF(B21<>"",EDATE(C20,1),"") -> 46447 | D21: =IF(B21<>"",G20,"") -> 214.25041 | E21: =IF(B21<>"",'Underwriting Dashboard'!F9,"") -> 801.32788 | F21: =IF(B21<>"",PPMT('Underwriting Dashboard'!F8,12,'Underwriting Dashboard'!C12,-'Underwriting Dashboard'!F7),"") -> 590.74182 | G21: =IF(B21<>"",IPMT('Underwriting Dashboard'!F8,12,'Underwriting Dashboard'!C12,-'Underwriting Dashboard'!F7),"") -> 210.58606 | H21: =IF(B21<>"",D21-F21,"") -> -376.49141
B22: =IF(13<='Underwriting Dashboard'!C12,13,"") -> 13 | C22: =IF(B22<>"",EDATE(C21,1),"") -> 46478 | D22: =IF(B22<>"",G21,"") -> 210.58606 | E22: =IF(B22<>"",'Underwriting Dashboard'!F9,"") -> 801.32788 | F22: =IF(B22<>"",PPMT('Underwriting Dashboard'!F8,13,'Underwriting Dashboard'!C12,-'Underwriting Dashboard'!F7),"") -> 594.42903 | G22: =IF(B22<>"",IPMT('Underwriting Dashboard'!F8,13,'Underwriting Dashboard'!C12,-'Underwriting Dashboard'!F7),"") -> 206.89885 | H22: =IF(B22<>"",D22-F22,"") -> -383.84297
B23: =IF(14<='Underwriting Dashboard'!C12,14,"") -> 14 | C23: =IF(B23<>"",EDATE(C22,1),"") -> 46508 | D23: =IF(B23<>"",G22,"") -> 206.89885 | E23: =IF(B23<>"",'Underwriting Dashboard'!F9,"") -> 801.32788 | F23: =IF(B23<>"",PPMT('Underwriting Dashboard'!F8,14,'Underwriting Dashboard'!C12,-'Underwriting Dashboard'!F7),"") -> 598.13926 | G23: =IF(B23<>"",IPMT('Underwriting Dashboard'!F8,14,'Underwriting Dashboard'!C12,-'Underwriting Dashboard'!F7),"") -> 203.18862 | H23: =IF(B23<>"",D23-F23,"") -> -391.24041
B24: =IF(15<='Underwriting Dashboard'!C12,15,"") -> 15 | C24: =IF(B24<>"",EDATE(C23,1),"") -> 46539 | D24: =IF(B24<>"",G23,"") -> 203.18862 | E24: =IF(B24<>"",'Underwriting Dashboard'!F9,"") -> 801.32788 | F24: =IF(B24<>"",PPMT('Underwriting Dashboard'!F8,15,'Underwriting Dashboard'!C12,-'Underwriting Dashboard'!F7),"") -> 601.87264 | G24: =IF(B24<>"",IPMT('Underwriting Dashboard'!F8,15,'Underwriting Dashboard'!C12,-'Underwriting Dashboard'!F7),"") -> 199.45524 | H24: =IF(B24<>"",D24-F24,"") -> -398.68402
B25: =IF(16<='Underwriting Dashboard'!C12,16,"") -> 16 | C25: =IF(B25<>"",EDATE(C24,1),"") -> 46569 | D25: =IF(B25<>"",G24,"") -> 199.45524 | E25: =IF(B25<>"",'Underwriting Dashboard'!F9,"") -> 801.32788 | F25: =IF(B25<>"",PPMT('Underwriting Dashboard'!F8,16,'Underwriting Dashboard'!C12,-'Underwriting Dashboard'!F7),"") -> 605.62933 | G25: =IF(B25<>"",IPMT('Underwriting Dashboard'!F8,16,'Underwriting Dashboard'!C12,-'Underwriting Dashboard'!F7),"") -> 195.69855 | H25: =IF(B25<>"",D25-F25,"") -> -406.17409
B26: =IF(17<='Underwriting Dashboard'!C12,17,"") -> 17 | C26: =IF(B26<>"",EDATE(C25,1),"") -> 46600 | D26: =IF(B26<>"",G25,"") -> 195.69855 | E26: =IF(B26<>"",'Underwriting Dashboard'!F9,"") -> 801.32788 | F26: =IF(B26<>"",PPMT('Underwriting Dashboard'!F8,17,'Underwriting Dashboard'!C12,-'Underwriting Dashboard'!F7),"") -> 609.40947 | G26: =IF(B26<>"",IPMT('Underwriting Dashboard'!F8,17,'Underwriting Dashboard'!C12,-'Underwriting Dashboard'!F7),"") -> 191.91841 | H26: =IF(B26<>"",D26-F26,"") -> -413.71092
B27: =IF(18<='Underwriting Dashboard'!C12,18,"") -> 18 | C27: =IF(B27<>"",EDATE(C26,1),"") -> 46631 | D27: =IF(B27<>"",G26,"") -> 191.91841 | E27: =IF(B27<>"",'Underwriting Dashboard'!F9,"") -> 801.32788 | F27: =IF(B27<>"",PPMT('Underwriting Dashboard'!F8,18,'Underwriting Dashboard'!C12,-'Underwriting Dashboard'!F7),"") -> 613.2132 | G27: =IF(B27<>"",IPMT('Underwriting Dashboard'!F8,18,'Underwriting Dashboard'!C12,-'Underwriting Dashboard'!F7),"") -> 188.11468 | H27: =IF(B27<>"",D27-F27,"") -> -421.29479
B28: =IF(19<='Underwriting Dashboard'!C12,19,"") -> 19 | C28: =IF(B28<>"",EDATE(C27,1),"") -> 46661 | D28: =IF(B28<>"",G27,"") -> 188.11468 | E28: =IF(B28<>"",'Underwriting Dashboard'!F9,"") -> 801.32788 | F28: =IF(B28<>"",PPMT('Underwriting Dashboard'!F8,19,'Underwriting Dashboard'!C12,-'Underwriting Dashboard'!F7),"") -> 617.04067 | G28: =IF(B28<>"",IPMT('Underwriting Dashboard'!F8,19,'Underwriting Dashboard'!C12,-'Underwriting Dashboard'!F7),"") -> 184.28721 | H28: =IF(B28<>"",D28-F28,"") -> -428.92599
B29: =IF(20<='Underwriting Dashboard'!C12,20,"") -> 20 | C29: =IF(B29<>"",EDATE(C28,1),"") -> 46692 | D29: =IF(B29<>"",G28,"") -> 184.28721 | E29: =IF(B29<>"",'Underwriting Dashboard'!F9,"") -> 801.32788 | F29: =IF(B29<>"",PPMT('Underwriting Dashboard'!F8,20,'Underwriting Dashboard'!C12,-'Underwriting Dashboard'!F7),"") -> 620.89203 | G29: =IF(B29<>"",IPMT('Underwriting Dashboard'!F8,20,'Underwriting Dashboard'!C12,-'Underwriting Dashboard'!F7),"") -> 180.43585 | H29: =IF(B29<>"",D29-F29,"") -> -436.60482
B30: =IF(21<='Underwriting Dashboard'!C12,21,"") -> 21 | C30: =IF(B30<>"",EDATE(C29,1),"") -> 46722 | D30: =IF(B30<>"",G29,"") -> 180.43585 | E30: =IF(B30<>"",'Underwriting Dashboard'!F9,"") -> 801.32788 | F30: =IF(B30<>"",PPMT('Underwriting Dashboard'!F8,21,'Underwriting Dashboard'!C12,-'Underwriting Dashboard'!F7),"") -> 624.76743 | G30: =IF(B30<>"",IPMT('Underwriting Dashboard'!F8,21,'Underwriting Dashboard'!C12,-'Underwriting Dashboard'!F7),"") -> 176.56045 | H30: =IF(B30<>"",D30-F30,"") -> -444.33159
B31: =IF(22<='Underwriting Dashboard'!C12,22,"") -> 22 | C31: =IF(B31<>"",EDATE(C30,1),"") -> 46753 | D31: =IF(B31<>"",G30,"") -> 176.56045 | E31: =IF(B31<>"",'Underwriting Dashboard'!F9,"") -> 801.32788 | F31: =IF(B31<>"",PPMT('Underwriting Dashboard'!F8,22,'Underwriting Dashboard'!C12,-'Underwriting Dashboard'!F7),"") -> 628.66702 | G31: =IF(B31<>"",IPMT('Underwriting Dashboard'!F8,22,'Underwriting Dashboard'!C12,-'Underwriting Dashboard'!F7),"") -> 172.66085 | H31: =IF(B31<>"",D31-F31,"") -> -452.10658
B32: =IF(23<='Underwriting Dashboard'!C12,23,"") -> 23 | C32: =IF(B32<>"",EDATE(C31,1),"") -> 46784 | D32: =IF(B32<>"",G31,"") -> 172.66085 | E32: =IF(B32<>"",'Underwriting Dashboard'!F9,"") -> 801.32788 | F32: =IF(B32<>"",PPMT('Underwriting Dashboard'!F8,23,'Underwriting Dashboard'!C12,-'Underwriting Dashboard'!F7),"") -> 632.59095 | G32: =IF(B32<>"",IPMT('Underwriting Dashboard'!F8,23,'Underwriting Dashboard'!C12,-'Underwriting Dashboard'!F7),"") -> 168.73692 | H32: =IF(B32<>"",D32-F32,"") -> -459.9301
B33: =IF(24<='Underwriting Dashboard'!C12,24,"") -> 24 | C33: =IF(B33<>"",EDATE(C32,1),"") -> 46813 | D33: =IF(B33<>"",G32,"") -> 168.73692 | E33: =IF(B33<>"",'Underwriting Dashboard'!F9,"") -> 801.32788 | F33: =IF(B33<>"",PPMT('Underwriting Dashboard'!F8,24,'Underwriting Dashboard'!C12,-'Underwriting Dashboard'!F7),"") -> 636.53938 | G33: =IF(B33<>"",IPMT('Underwriting Dashboard'!F8,24,'Underwriting Dashboard'!C12,-'Underwriting Dashboard'!F7),"") -> 164.7885 | H33: =IF(B33<>"",D33-F33,"") -> -467.80245
B34: =IF(25<='Underwriting Dashboard'!C12,25,"") -> 25 | C34: =IF(B34<>"",EDATE(C33,1),"") -> 46844 | D34: =IF(B34<>"",G33,"") -> 164.7885 | E34: =IF(B34<>"",'Underwriting Dashboard'!F9,"") -> 801.32788 | F34: =IF(B34<>"",PPMT('Underwriting Dashboard'!F8,25,'Underwriting Dashboard'!C12,-'Underwriting Dashboard'!F7),"") -> 640.51244 | G34: =IF(B34<>"",IPMT('Underwriting Dashboard'!F8,25,'Underwriting Dashboard'!C12,-'Underwriting Dashboard'!F7),"") -> 160.81544 | H34: =IF(B34<>"",D34-F34,"") -> -475.72394
B35: =IF(26<='Underwriting Dashboard'!C12,26,"") -> 26 | C35: =IF(B35<>"",EDATE(C34,1),"") -> 46874 | D35: =IF(B35<>"",G34,"") -> 160.81544 | E35: =IF(B35<>"",'Underwriting Dashboard'!F9,"") -> 801.32788 | F35: =IF(B35<>"",PPMT('Underwriting Dashboard'!F8,26,'Underwriting Dashboard'!C12,-'Underwriting Dashboard'!F7),"") -> 644.51031 | G35: =IF(B35<>"",IPMT('Underwriting Dashboard'!F8,26,'Underwriting Dashboard'!C12,-'Underwriting Dashboard'!F7),"") -> 156.81757 | H35: =IF(B35<>"",D35-F35,"") -> -483.69487
B36: =IF(27<='Underwriting Dashboard'!C12,27,"") -> 27 | C36: =IF(B36<>"",EDATE(C35,1),"") -> 46905 | D36: =IF(B36<>"",G35,"") -> 156.81757 | E36: =IF(B36<>"",'Underwriting Dashboard'!F9,"") -> 801.32788 | F36: =IF(B36<>"",PPMT('Underwriting Dashboard'!F8,27,'Underwriting Dashboard'!C12,-'Underwriting Dashboard'!F7),"") -> 648.53313 | G36: =IF(B36<>"",IPMT('Underwriting Dashboard'!F8,27,'Underwriting Dashboard'!C12,-'Underwriting Dashboard'!F7),"") -> 152.79475 | H36: =IF(B36<>"",D36-F36,"") -> -491.71555
B37: =IF(28<='Underwriting Dashboard'!C12,28,"") -> 28 | C37: =IF(B37<>"",EDATE(C36,1),"") -> 46935 | D37: =IF(B37<>"",G36,"") -> 152.79475 | E37: =IF(B37<>"",'Underwriting Dashboard'!F9,"") -> 801.32788 | F37: =IF(B37<>"",PPMT('Underwriting Dashboard'!F8,28,'Underwriting Dashboard'!C12,-'Underwriting Dashboard'!F7),"") -> 652.58105 | G37: =IF(B37<>"",IPMT('Underwriting Dashboard'!F8,28,'Underwriting Dashboard'!C12,-'Underwriting Dashboard'!F7),"") -> 148.74683 | H37: =IF(B37<>"",D37-F37,"") -> -499.7863
B38: =IF(29<='Underwriting Dashboard'!C12,29,"") -> 29 | C38: =IF(B38<>"",EDATE(C37,1),"") -> 46966 | D38: =IF(B38<>"",G37,"") -> 148.74683 | E38: =IF(B38<>"",'Underwriting Dashboard'!F9,"") -> 801.32788 | F38: =IF(B38<>"",PPMT('Underwriting Dashboard'!F8,29,'Underwriting Dashboard'!C12,-'Underwriting Dashboard'!F7),"") -> 656.65425 | G38: =IF(B38<>"",IPMT('Underwriting Dashboard'!F8,29,'Underwriting Dashboard'!C12,-'Underwriting Dashboard'!F7),"") -> 144.67363 | H38: =IF(B38<>"",D38-F38,"") -> -507.90742
B39: =IF(30<='Underwriting Dashboard'!C12,30,"") -> 30 | C39: =IF(B39<>"",EDATE(C38,1),"") -> 46997 | D39: =IF(B39<>"",G38,"") -> 144.67363 | E39: =IF(B39<>"",'Underwriting Dashboard'!F9,"") -> 801.32788 | F39: =IF(B39<>"",PPMT('Underwriting Dashboard'!F8,30,'Underwriting Dashboard'!C12,-'Underwriting Dashboard'!F7),"") -> 660.75286 | G39: =IF(B39<>"",IPMT('Underwriting Dashboard'!F8,30,'Underwriting Dashboard'!C12,-'Underwriting Dashboard'!F7),"") -> 140.57501 | H39: =IF(B39<>"",D39-F39,"") -> -516.07923
B40: =IF(31<='Underwriting Dashboard'!C12,31,"") -> 31 | C40: =IF(B40<>"",EDATE(C39,1),"") -> 47027 | D40: =IF(B40<>"",G39,"") -> 140.57501 | E40: =IF(B40<>"",'Underwriting Dashboard'!F9,"") -> 801.32788 | F40: =IF(B40<>"",PPMT('Underwriting Dashboard'!F8,31,'Underwriting Dashboard'!C12,-'Underwriting Dashboard'!F7),"") -> 664.87706 | G40: =IF(B40<>"",IPMT('Underwriting Dashboard'!F8,31,'Underwriting Dashboard'!C12,-'Underwriting Dashboard'!F7),"") -> 136.45082 | H40: =IF(B40<>"",D40-F40,"") -> -524.30205
B41: =IF(32<='Underwriting Dashboard'!C12,32,"") -> 32 | C41: =IF(B41<>"",EDATE(C40,1),"") -> 47058 | D41: =IF(B41<>"",G40,"") -> 136.45082 | E41: =IF(B41<>"",'Underwriting Dashboard'!F9,"") -> 801.32788 | F41: =IF(B41<>"",PPMT('Underwriting Dashboard'!F8,32,'Underwriting Dashboard'!C12,-'Underwriting Dashboard'!F7),"") -> 669.027 | G41: =IF(B41<>"",IPMT('Underwriting Dashboard'!F8,32,'Underwriting Dashboard'!C12,-'Underwriting Dashboard'!F7),"") -> 132.30087 | H41: =IF(B41<>"",D41-F41,"") -> -532.57619
B42: =IF(33<='Underwriting Dashboard'!C12,33,"") -> 33 | C42: =IF(B42<>"",EDATE(C41,1),"") -> 47088 | D42: =IF(B42<>"",G41,"") -> 132.30087 | E42: =IF(B42<>"",'Underwriting Dashboard'!F9,"") -> 801.32788 | F42: =IF(B42<>"",PPMT('Underwriting Dashboard'!F8,33,'Underwriting Dashboard'!C12,-'Underwriting Dashboard'!F7),"") -> 673.20285 | G42: =IF(B42<>"",IPMT('Underwriting Dashboard'!F8,33,'Underwriting Dashboard'!C12,-'Underwriting Dashboard'!F7),"") -> 128.12503 | H42: =IF(B42<>"",D42-F42,"") -> -540.90197
B43: =IF(34<='Underwriting Dashboard'!C12,34,"") -> 34 | C43: =IF(B43<>"",EDATE(C42,1),"") -> 47119 | D43: =IF(B43<>"",G42,"") -> 128.12503 | E43: =IF(B43<>"",'Underwriting Dashboard'!F9,"") -> 801.32788 | F43: =IF(B43<>"",PPMT('Underwriting Dashboard'!F8,34,'Underwriting Dashboard'!C12,-'Underwriting Dashboard'!F7),"") -> 677.40476 | G43: =IF(B43<>"",IPMT('Underwriting Dashboard'!F8,34,'Underwriting Dashboard'!C12,-'Underwriting Dashboard'!F7),"") -> 123.92312 | H43: =IF(B43<>"",D43-F43,"") -> -549.27972
B44: =IF(35<='Underwriting Dashboard'!C12,35,"") -> 35 | C44: =IF(B44<>"",EDATE(C43,1),"") -> 47150 | D44: =IF(B44<>"",G43,"") -> 123.92312 | E44: =IF(B44<>"",'Underwriting Dashboard'!F9,"") -> 801.32788 | F44: =IF(B44<>"",PPMT('Underwriting Dashboard'!F8,35,'Underwriting Dashboard'!C12,-'Underwriting Dashboard'!F7),"") -> 681.63289 | G44: =IF(B44<>"",IPMT('Underwriting Dashboard'!F8,35,'Underwriting Dashboard'!C12,-'Underwriting Dashboard'!F7),"") -> 119.69499 | H44: =IF(B44<>"",D44-F44,"") -> -557.70977
...
