Workbook

Sheet Instructions
A1: MANUFACTURING JOB COST ESTIMATOR — USER GUIDE | D1: Quanthaven Labs, LLC
A3: OVERVIEW
B5: This workbook calculates the fully-loaded cost and quoted price for a manufacturing job. Enter your inputs in the blue cells on the Estimator tab. All gray cells are formula-driven and locked. The summary at the bottom of the Estimator sheet automatically rolls up cost, markup, and margin. Use the Rate Table tab to maintain standard labor and burden rates for reference.
A7: COLOR CODING
B9: Blue text on white | C9: User input cell — type your values here. These cells are unlocked.
B10: Black text on gray | C10: Calculated formula — do not edit. These cells are protected.
B11: Black text on amber | C11: Subtotal or key output — formula-driven summary value.
B12: Black text on light blue | C12: Column or section header — label only, no input required.
B13: White text on dark navy | C13: Section title or totals row — structural label.
A15: STEP-BY-STEP INSTRUCTIONS
B17: Step 1 | C17: Enter Job Information
B18: At the top of the Estimator tab, fill in the job name, customer, part number, production quantity, date, and your name. Quantity is used to calculate per-unit cost and price in the Key Metrics section.
B20: Step 2 | C20: Enter Material Costs (Section 1)
B21: For each raw material, enter a description, unit cost, quantity, and unit of measure. Optionally enter a waste % (e.g., 5% for 0.05) to account for scrap or yield loss — the extended cost will automatically inflate by that factor. Leave unused rows blank; they will display a dash and be excluded from totals.
B23: Step 3 | C23: Enter Labor (Section 2)
B24: List each operation or work center (e.g., CNC Machining, Welding, Assembly). Enter estimated hours and the applicable hourly rate. Extended cost calculates automatically. Reference the Rate Table tab for your standard labor rates.
B26: Step 4 | C26: Enter Machine Time (Section 3)
B27: For each machine or resource, enter setup hours and run hours separately. Total hours are summed automatically. Enter the burden rate ($/hr) for that machine. Burden rates should include depreciation, maintenance, utilities, and allocated overhead. See the Rate Table tab for standard burden rates.
B29: Step 5 | C29: Enter Fixed Overhead (Section 4)
B30: Enter any fixed job-level cost not captured above — tooling, fixtures, freight, outside processing, etc. This is a single dollar input applied at the job level.
B32: Step 6 | C32: Set Markup Percentages (Section 4)
B33: Four independent markup fields let you apply different margins by cost type: material, labor, machine, and overhead. Default values are pre-filled (15% / 20% / 10% / 8%). Adjust these to reflect your quoting policy or job-specific requirements.
B35: Step 7 | C35: Review the Estimate Summary (Section 5)
B36: The summary table shows base cost, markup %, markup dollar amount, and quoted price for each category, plus each category's share of the total quote. The totals row and Key Metrics box calculate automatically.
B38: Step 8 | C38: Review Key Metrics
B39: At the bottom of the summary, review total job cost, total quoted amount, gross profit, gross margin %, unit cost, and unit quote price. These update instantly as you modify any input.
A42: TIPS & NOTES
B44: Sheet Protection
B45: Formula cells are protected to prevent accidental edits. If you need to modify a formula, use Review > Unprotect Sheet. Password: quanthaven
B46: Rate Table
B47: The Rate Table tab contains editable reference rates for labor and machines. Values there do not feed directly into the Estimator — copy rates manually as needed.
B48: Unused Rows
B49: Any row left blank will show a dash (-) in the Extended Cost column and will be excluded from subtotals. You do not need to delete empty rows.
B50: Waste / Yield
B51: Enter waste % as a decimal (e.g., 5% = 0.05) or as a percentage-formatted cell. A 5% waste factor on $100 of material will calculate to $105 extended cost.
B52: Saving Versions
B53: Save a copy with the job name and date in the filename (e.g., Bracket_Assembly_PN0042_2026-03-30.xlsx) to maintain a quote history.

Sheet Estimator
A1: MANUFACTURING JOB COST ESTIMATOR | K1: Quanthaven Labs, LLC
A3: JOB INFORMATION
B4: Job / Part Name | C4: Customer | D4: Part No. | E4: Qty | F4: Date | G4: Estimator
F5: 46105
A7: SECTION 1 — MATERIALS | I7: Material Rate Reference
B8: Material ▾ | C8: Unit Cost ($) ↻ | D8: Qty | E8: Unit ↻ | F8: Waste % | G8: Extended ($) | I8: Material | J8: Unit Cost ($) | K8: Unit | L8: Notes
C9: =IFERROR(VLOOKUP(B9,'Rate Table'!$B$24:$D$31,2,FALSE()),"") | E9: =IFERROR(VLOOKUP(B9,'Rate Table'!$B$24:$D$31,3,FALSE()),"") | G9: =IF(OR(C9="",D9=""),"-",C9*D9*(1+IF(F9="",0,F9))) -> - | I9: ='Rate Table'!B24 -> Steel Sheet, 11ga | J9: ='Rate Table'!C24 -> 1.85 | K9: ='Rate Table'!D24 -> sqft | L9: ='Rate Table'!E24 -> Hot-rolled
C10: =IFERROR(VLOOKUP(B10,'Rate Table'!$B$24:$D$31,2,FALSE()),"") | E10: =IFERROR(VLOOKUP(B10,'Rate Table'!$B$24:$D$31,3,FALSE()),"") | G10: =IF(OR(C10="",D10=""),"-",C10*D10*(1+IF(F10="",0,F10))) -> - | I10: ='Rate Table'!B25 -> Aluminum Plate, 1/4" | J10: ='Rate Table'!C25 -> 4.2 | K10: ='Rate Table'!D25 -> sqft | L10: ='Rate Table'!E25 -> 6061-T6
C11: =IFERROR(VLOOKUP(B11,'Rate Table'!$B$24:$D$31,2,FALSE()),"") | E11: =IFERROR(VLOOKUP(B11,'Rate Table'!$B$24:$D$31,3,FALSE()),"") | G11: =IF(OR(C11="",D11=""),"-",C11*D11*(1+IF(F11="",0,F11))) -> - | I11: ='Rate Table'!B26 -> Steel Tube, 2x2x.120 | J11: ='Rate Table'!C26 -> 3.1 | K11: ='Rate Table'!D26 -> ft | L11: ='Rate Table'!E26 -> A500 square
C12: =IFERROR(VLOOKUP(B12,'Rate Table'!$B$24:$D$31,2,FALSE()),"") | E12: =IFERROR(VLOOKUP(B12,'Rate Table'!$B$24:$D$31,3,FALSE()),"") | G12: =IF(OR(C12="",D12=""),"-",C12*D12*(1+IF(F12="",0,F12))) -> - | I12: ='Rate Table'!B27 -> Hardware / Fasteners | J12: ='Rate Table'!C27 -> 0.15 | K12: ='Rate Table'!D27 -> ea | L12: ='Rate Table'!E27 -> Avg per piece
C13: =IFERROR(VLOOKUP(B13,'Rate Table'!$B$24:$D$31,2,FALSE()),"") | E13: =IFERROR(VLOOKUP(B13,'Rate Table'!$B$24:$D$31,3,FALSE()),"") | G13: =IF(OR(C13="",D13=""),"-",C13*D13*(1+IF(F13="",0,F13))) -> - | I13: ='Rate Table'!B28 -> Welding Wire / Consumables | J13: ='Rate Table'!C28 -> 0.5 | K13: ='Rate Table'!D28 -> lb | L13: ='Rate Table'!E28 -> ER70S-6
C14: =IFERROR(VLOOKUP(B14,'Rate Table'!$B$24:$D$31,2,FALSE()),"") | E14: =IFERROR(VLOOKUP(B14,'Rate Table'!$B$24:$D$31,3,FALSE()),"") | G14: =IF(OR(C14="",D14=""),"-",C14*D14*(1+IF(F14="",0,F14))) -> - | I14: ='Rate Table'!B29 -> Paint / Powder Coat | J14: ='Rate Table'!C29 -> 1.2 | K14: ='Rate Table'!D29 -> sqft | L14: ='Rate Table'!E29 -> Single coat
C15: =IFERROR(VLOOKUP(B15,'Rate Table'!$B$24:$D$31,2,FALSE()),"") | E15: =IFERROR(VLOOKUP(B15,'Rate Table'!$B$24:$D$31,3,FALSE()),"") | G15: =IF(OR(C15="",D15=""),"-",C15*D15*(1+IF(F15="",0,F15))) -> - | I15: ='Rate Table'!B30 -> Aluminum Extrusion | J15: ='Rate Table'!C30 -> 2.8 | K15: ='Rate Table'!D30 -> ft | L15: ='Rate Table'!E30 -> 6063-T5
C16: =IFERROR(VLOOKUP(B16,'Rate Table'!$B$24:$D$31,2,FALSE()),"") | E16: =IFERROR(VLOOKUP(B16,'Rate Table'!$B$24:$D$31,3,FALSE()),"") | G16: =IF(OR(C16="",D16=""),"-",C16*D16*(1+IF(F16="",0,F16))) -> - | I16: ='Rate Table'!B31 -> Misc Raw Material | J16: ='Rate Table'!C31 -> 1 | K16: ='Rate Table'!D31 -> ea | L16: ='Rate Table'!E31 -> Adjust as needed
C17: =IFERROR(VLOOKUP(B17,'Rate Table'!$B$24:$D$31,2,FALSE()),"") | E17: =IFERROR(VLOOKUP(B17,'Rate Table'!$B$24:$D$31,3,FALSE()),"") | G17: =IF(OR(C17="",D17=""),"-",C17*D17*(1+IF(F17="",0,F17))) -> -
C18: =IFERROR(VLOOKUP(B18,'Rate Table'!$B$24:$D$31,2,FALSE()),"") | E18: =IFERROR(VLOOKUP(B18,'Rate Table'!$B$24:$D$31,3,FALSE()),"") | G18: =IF(OR(C18="",D18=""),"-",C18*D18*(1+IF(F18="",0,F18))) -> -
B19: Material Subtotal | G19: =SUM(G9:G18) -> 0
A21: SECTION 2 — LABOR | I21: Labor Rate Reference
B22: Operation ▾ | C22: Hours | F22: Rate ($/hr) ↻ | G22: Extended ($) | I22: Operation / Role | J22: Reg ($/hr) | K22: OT ($/hr) | L22: Notes
F23: =IFERROR(VLOOKUP(B23,'Rate Table'!$B$5:$C$9,2,FALSE()),"") | G23: =IF(OR(C23="",F23=""),"-",C23*F23) -> - | I23: ='Rate Table'!B5 -> General Labor | J23: ='Rate Table'!C5 -> 18 | K23: ='Rate Table'!D5 -> 27 | L23: ='Rate Table'!E5 -> 0
F24: =IFERROR(VLOOKUP(B24,'Rate Table'!$B$5:$C$9,2,FALSE()),"") | G24: =IF(OR(C24="",F24=""),"-",C24*F24) -> - | I24: ='Rate Table'!B6 -> Skilled Machinist | J24: ='Rate Table'!C6 -> 28 | K24: ='Rate Table'!D6 -> 42 | L24: ='Rate Table'!E6 -> CNC, lathe
F25: =IFERROR(VLOOKUP(B25,'Rate Table'!$B$5:$C$9,2,FALSE()),"") | G25: =IF(OR(C25="",F25=""),"-",C25*F25) -> - | I25: ='Rate Table'!B7 -> Welder / Fabricator | J25: ='Rate Table'!C7 -> 26 | K25: ='Rate Table'!D7 -> 39 | L25: ='Rate Table'!E7 -> 0
F26: =IFERROR(VLOOKUP(B26,'Rate Table'!$B$5:$C$9,2,FALSE()),"") | G26: =IF(OR(C26="",F26=""),"-",C26*F26) -> - | I26: ='Rate Table'!B8 -> Assembly Tech | J26: ='Rate Table'!C8 -> 22 | K26: ='Rate Table'!D8 -> 33 | L26: ='Rate Table'!E8 -> 0
F27: =IFERROR(VLOOKUP(B27,'Rate Table'!$B$5:$C$9,2,FALSE()),"") | G27: =IF(OR(C27="",F27=""),"-",C27*F27) -> - | I27: ='Rate Table'!B9 -> Quality Inspector | J27: ='Rate Table'!C9 -> 24 | K27: ='Rate Table'!D9 -> 36 | L27: ='Rate Table'!E9 -> 0
F28: =IFERROR(VLOOKUP(B28,'Rate Table'!$B$5:$C$9,2,FALSE()),"") | G28: =IF(OR(C28="",F28=""),"-",C28*F28) -> -
F29: =IFERROR(VLOOKUP(B29,'Rate Table'!$B$5:$C$9,2,FALSE()),"") | G29: =IF(OR(C29="",F29=""),"-",C29*F29) -> -
F30: =IFERROR(VLOOKUP(B30,'Rate Table'!$B$5:$C$9,2,FALSE()),"") | G30: =IF(OR(C30="",F30=""),"-",C30*F30) -> -
B31: Labor Subtotal | G31: =SUM(G23:G30) -> 0
A33: SECTION 3 — MACHINE TIME & BURDEN | I33: Machine Rate Reference
B34: Machine ▾ | C34: Setup Hrs | D34: Run Hrs | E34: Total Hrs | F34: Burden ($/hr) ↻ | G34: Extended ($) | I34: Machine / Resource | J34: Burden ($/hr) | K34: Capacity (hrs/d) | L34: Notes
E35: =IF(AND(C35="",D35=""),"-",IF(C35="",0,C35)+IF(D35="",0,D35)) -> - | F35: =IFERROR(VLOOKUP(B35,'Rate Table'!$B$14:$C$19,2,FALSE()),"") | G35: =IF(OR(E35="-",E35=0,F35=""),"-",E35*F35) -> - | I35: ='Rate Table'!B14 -> CNC Machining Center | J35: ='Rate Table'!C14 -> 85 | K35: ='Rate Table'!D14 -> 20 | L35: ='Rate Table'!E14 -> 3-axis
E36: =IF(AND(C36="",D36=""),"-",IF(C36="",0,C36)+IF(D36="",0,D36)) -> - | F36: =IFERROR(VLOOKUP(B36,'Rate Table'!$B$14:$C$19,2,FALSE()),"") | G36: =IF(OR(E36="-",E36=0,F36=""),"-",E36*F36) -> - | I36: ='Rate Table'!B15 -> Laser Cutter | J36: ='Rate Table'!C15 -> 60 | K36: ='Rate Table'!D15 -> 18 | L36: ='Rate Table'!E15 -> Fiber, up to 1" steel
E37: =IF(AND(C37="",D37=""),"-",IF(C37="",0,C37)+IF(D37="",0,D37)) -> - | F37: =IFERROR(VLOOKUP(B37,'Rate Table'!$B$14:$C$19,2,FALSE()),"") | G37: =IF(OR(E37="-",E37=0,F37=""),"-",E37*F37) -> - | I37: ='Rate Table'!B16 -> Press Brake | J37: ='Rate Table'!C16 -> 45 | K37: ='Rate Table'!D16 -> 20 | L37: ='Rate Table'!E16 -> 0
E38: =IF(AND(C38="",D38=""),"-",IF(C38="",0,C38)+IF(D38="",0,D38)) -> - | F38: =IFERROR(VLOOKUP(B38,'Rate Table'!$B$14:$C$19,2,FALSE()),"") | G38: =IF(OR(E38="-",E38=0,F38=""),"-",E38*F38) -> - | I38: ='Rate Table'!B17 -> MIG Welder | J38: ='Rate Table'!C17 -> 35 | K38: ='Rate Table'!D17 -> 16 | L38: ='Rate Table'!E17 -> Per station
E39: =IF(AND(C39="",D39=""),"-",IF(C39="",0,C39)+IF(D39="",0,D39)) -> - | F39: =IFERROR(VLOOKUP(B39,'Rate Table'!$B$14:$C$19,2,FALSE()),"") | G39: =IF(OR(E39="-",E39=0,F39=""),"-",E39*F39) -> - | I39: ='Rate Table'!B18 -> Surface Grinder | J39: ='Rate Table'!C18 -> 50 | K39: ='Rate Table'!D18 -> 16 | L39: ='Rate Table'!E18 -> 0
E40: =IF(AND(C40="",D40=""),"-",IF(C40="",0,C40)+IF(D40="",0,D40)) -> - | F40: =IFERROR(VLOOKUP(B40,'Rate Table'!$B$14:$C$19,2,FALSE()),"") | G40: =IF(OR(E40="-",E40=0,F40=""),"-",E40*F40) -> - | I40: ='Rate Table'!B19 -> Assembly Station | J40: ='Rate Table'!C19 -> 25 | K40: ='Rate Table'!D19 -> 20 | L40: ='Rate Table'!E19 -> 0
E41: =IF(AND(C41="",D41=""),"-",IF(C41="",0,C41)+IF(D41="",0,D41)) -> - | F41: =IFERROR(VLOOKUP(B41,'Rate Table'!$B$14:$C$19,2,FALSE()),"") | G41: =IF(OR(E41="-",E41=0,F41=""),"-",E41*F41) -> -
E42: =IF(AND(C42="",D42=""),"-",IF(C42="",0,C42)+IF(D42="",0,D42)) -> - | F42: =IFERROR(VLOOKUP(B42,'Rate Table'!$B$14:$C$19,2,FALSE()),"") | G42: =IF(OR(E42="-",E42=0,F42=""),"-",E42*F42) -> -
B43: Machine Subtotal | G43: =SUM(G35:G42) -> 0
A45: SECTION 4 — OVERHEAD & MARKUP ASSUMPTIONS
...

Sheet Rate Table
A1: LABOR, MACHINE & MATERIAL RATE REFERENCE | E1: Quanthaven Labs, LLC
A3: Labor Rates
B4: Role / Operation | C4: Hourly Rate ($) | D4: OT Rate ($) | E4: Notes
B5: General Labor | C5: 18 | D5: 27
B6: Skilled Machinist | C6: 28 | D6: 42 | E6: CNC, lathe
B7: Welder / Fabricator | C7: 26 | D7: 39
B8: Assembly Tech | C8: 22 | D8: 33
B9: Quality Inspector | C9: 24 | D9: 36
A12: Machine Burden Rates
B13: Machine / Resource | C13: Burden Rate ($/hr) | D13: Capacity (hrs/day) | E13: Notes
B14: CNC Machining Center | C14: 85 | D14: 20 | E14: 3-axis
B15: Laser Cutter | C15: 60 | D15: 18 | E15: Fiber, up to 1" steel
B16: Press Brake | C16: 45 | D16: 20
B17: MIG Welder | C17: 35 | D17: 16 | E17: Per station
B18: Surface Grinder | C18: 50 | D18: 16
B19: Assembly Station | C19: 25 | D19: 20
A22: Material / Supply Costs
B23: Material / Description | C23: Unit Cost ($) | D23: Unit | E23: Notes
B24: Steel Sheet, 11ga | C24: 1.85 | D24: sqft | E24: Hot-rolled
B25: Aluminum Plate, 1/4" | C25: 4.2 | D25: sqft | E25: 6061-T6
B26: Steel Tube, 2x2x.120 | C26: 3.1 | D26: ft | E26: A500 square
B27: Hardware / Fasteners | C27: 0.15 | D27: ea | E27: Avg per piece
B28: Welding Wire / Consumables | C28: 0.5 | D28: lb | E28: ER70S-6
B29: Paint / Powder Coat | C29: 1.2 | D29: sqft | E29: Single coat
B30: Aluminum Extrusion | C30: 2.8 | D30: ft | E30: 6063-T5
B31: Misc Raw Material | C31: 1 | D31: ea | E31: Adjust as needed
B33: All blue cells are editable. Dropdown selections on the Estimator tab pull from this table automatically.
