Workbook

Sheet 📊 Dashboard
B1: 📊 14-UNIT MULTIFAMILY — RETURN SUMMARY
B2: 1247 Maple Grove Drive, Columbus OH | Acquired March 2021 | As of March 2025
B5: PURCHASE PRICE | D5: EQUITY INVESTED | F5: CURRENT EST. VALUE
B6: ='🏢 Acquisition'!C16 -> 1650000 | D6: ='🏢 Acquisition'!C39 -> 472762 | F6: ='💰 Return Analysis'!C5 -> 1970000
B10: TOTAL CASH FLOW (CUMUL.) | D10: EQUITY MULTIPLE | F10: LEVERAGED IRR
B11: ='📈 Operating History'!H33 -> -38458.295 | D11: ='💰 Return Analysis'!C30 -> 1.742026 | F11: ='💰 Return Analysis'!C49 -> 0.051096378
B15: 2024 NOI | D15: CURRENT CAP RATE | F15: 2024 DSCR
B16: ='📈 Operating History'!F31 -> 68763 | D16: ='💰 Return Analysis'!C16 -> 0.02873697 | F16: ='💰 Return Analysis'!C19 -> 0.94127456
B20: ANNUAL PERFORMANCE SUMMARY
B21: Metric | C21: 2021 | D21: 2022 | E21: 2023 | F21: 2024 | G21: 2025 YTD
B22: Effective Gross Income (EGI) | C22: ='📈 Operating History'!C15 -> 108696 | D22: ='📈 Operating History'!D15 -> 124596 | E22: ='📈 Operating History'!E15 -> 133440 | F22: ='📈 Operating History'!F15 -> 142008 | G22: ='📈 Operating History'!G15 -> 36318
B23: Total Operating Expenses | C23: ='📈 Operating History'!C30 -> -61280 | D23: ='📈 Operating History'!D30 -> -60158 | E23: ='📈 Operating History'!E30 -> -80453 | F23: ='📈 Operating History'!F30 -> -73245 | G23: ='📈 Operating History'!G30 -> -16168
B24: Net Operating Income (NOI) | C24: ='📈 Operating History'!C31 -> 47416 | D24: ='📈 Operating History'!D31 -> 64438 | E24: ='📈 Operating History'!E31 -> 52987 | F24: ='📈 Operating History'!F31 -> 68763 | G24: ='📈 Operating History'!G31 -> 20150
B25: Annual Debt Service | C25: ='📈 Operating History'!C32 -> -54789.805 | D25: ='📈 Operating History'!D32 -> -73053.074 | E25: ='📈 Operating History'!E32 -> -73053.074 | F25: ='📈 Operating History'!F32 -> -73053.074 | G25: ='📈 Operating History'!G32 -> -18263.268
B26: Cash Flow Before Tax (CFBT) | C26: ='📈 Operating History'!C33 -> -7373.8054 | D26: ='📈 Operating History'!D33 -> -8615.0738 | E26: ='📈 Operating History'!E33 -> -20066.074 | F26: ='📈 Operating History'!F33 -> -4290.0738 | G26: ='📈 Operating History'!G33 -> 1886.7315
B27: Cash-on-Cash Return | C27: ='📈 Operating History'!C33/'🏢 Acquisition'!C39 -> -0.015597289 | D27: ='📈 Operating History'!D33/'🏢 Acquisition'!C39 -> -0.018222856 | E27: ='📈 Operating History'!E33/'🏢 Acquisition'!C39 -> -0.042444346 | F27: ='📈 Operating History'!F33/'🏢 Acquisition'!C39 -> -0.0090744895 | G27: ='📈 Operating History'!G33/'🏢 Acquisition'!C39 -> 0.0039908697
B30: WEALTH CREATION SUMMARY
B31: Component | C31: Amount | D31: Notes
B32: Cumulative Cash Flow Distributions | C32: ='💰 Return Analysis'!C27 -> 320000
B33: Unrealized Appreciation (Market) | C33: ='💰 Return Analysis'!C28 -> 69260
B34: Equity Buildup (Loan Paydown) | C34: ='💰 Return Analysis'!C29 -> 350801.7
B35: TOTAL WEALTH CREATED | C35: ='💰 Return Analysis'!C30 -> 1.742026
B36: Equity Multiple | C36: ='💰 Return Analysis'!C31 -> 0.18945345
B37: Annualized Return | C37: ='💰 Return Analysis'!C32 -> 0
B38: Leveraged IRR | C38: ='💰 Return Analysis'!C49 -> 0.051096378

Sheet 🏢 Acquisition
B1: 🏢 ACQUISITION & CLOSING STATEMENT
B2: Source: HUD-1 / ALTA Settlement Statement | Enter exact figures from closing documents
B4: PROPERTY INFORMATION
B5: Property Address | C5: 1247 Maple Grove Drive, Columbus OH 43215
B6: Property Type | C6: Multifamily — 14 Units
B7: Acquisition Date | C7: 2021-03-15
B8: Analysis Date (Today) | C8: 2025-03-01
B9: Holding Period (months) | C9: =DATEDIF(C7,C8,"M") -> 47
B10: Holding Period (years) | C10: =C9/12 -> 3.9166667
B11: Unit Count | C11: 14
B12: Unit Mix | C12: 8 × 1BR / 6 × 2BR
B14: PURCHASE ECONOMICS
B15: Item | C15: Amount ($) | D15: Notes
B16: Contract Purchase Price | C16: 1650000 | D16: Negotiated price per PSA
B17: Earnest Money Deposit | C17: 25000 | D17: Applied at closing
B18: Loan Origination Fee | C18: 4950 | D18: 0.40% of loan amount
B19: Title Insurance | C19: 3200 | D19: Owner + lender policy
B20: Attorney / Closing Fees | C20: 2800 | D20: Settlement agent
B21: Recording Fees | C21: 480 | D21: County recorder
B22: Property Inspection | C22: 1200 | D22: Pre-closing inspection
B23: Environmental Report | C23: 1800 | D23: Phase I ESA
B24: Appraisal | C24: 2500 | D24: Required by lender
B25: Prorated Property Taxes | C25: 4812 | D25: Seller credit at closing
B26: Prorated Rents (Seller Credit) | C26: 3920 | D26: Tenant rents prepaid — credit to buyer
B27: Security Deposits Assumed | C27: 8400 | D27: 14 units × $600 avg — assumed liability
B28: Other Closing Costs | C28: 1200 | D28: Misc. lender fees
B29: TOTAL ACQUISITION COST | C29: =SUM(C16:C28) -> 1710262
B31: FINANCING STRUCTURE
B32: Item | C32: Amount / Rate | D32: Notes
B33: Original Loan Amount | C33: 1237500 | D33: 75% LTV conventional
B34: Loan-to-Value (LTV) | C34: =C33/C16 -> 0.75 | D34: At origination
B35: Interest Rate (Fixed) | C35: 0.0425 | D35: 30-yr fixed, conventional
B36: Loan Term (months) | C36: 360 | D36: 30-year amortization
B37: Monthly Mortgage Payment | C37: =PMT(C35/12,C36,-C33) -> 6087.7562 | D37: P&I only
B38: Annual Debt Service | C38: =C37*12 -> 73053.074 | D38: Total annual P&I
B39: Equity Invested at Close | C39: =C29-C33 -> 472762 | D39: Total cost minus loan
B40: Down Payment % | C40: =C39/C16 -> 0.28652242 | D40: Equity / purchase price

Sheet 📈 Operating History
B1: 📈 OPERATING HISTORY — ANNUAL P&L
B2: Source: Management Company Annual Statements | Blue = inputs from reports | Reconciles to bank records
B4: Line Item | C4: 2021 | D4: 2022 | E4: 2023 | F4: 2024 | G4: 2025 YTD | H4: Cumulative Total
B5: GROSS POTENTIAL RENT (GPR)
B6: Scheduled Rent Income | C6: 118440 | D6: 131040 | E6: 138720 | F6: 145440 | G6: 37128 | H6: =SUM(C6:G6) -> 570768
B7: Vacancy Loss | C7: -9024 | D7: -8244 | E7: -7560 | F7: -6432 | G7: -1560 | H7: =SUM(C7:G7) -> -32820
B8: Concessions / Lease-Up Loss | C8: -2100 | D8: -600 | E8: -300 | F8: 0 | G8: 0 | H8: =SUM(C8:G8) -> -3000
B9: Bad Debt / Write-offs | C9: -1800 | D9: -1200 | E9: -900 | F9: -600 | G9: -120 | H9: =SUM(C9:G9) -> -4620
B10: OTHER INCOME
B11: Late Fees | C11: 1080 | D11: 1200 | E11: 960 | F11: 840 | G11: 180 | H11: =SUM(C11:G11) -> 4260
B12: Laundry / Vending | C12: 720 | D12: 840 | E12: 900 | F12: 960 | G12: 240 | H12: =SUM(C12:G12) -> 3660
B13: Pet Fees | C13: 420 | D13: 480 | E13: 540 | F13: 600 | G13: 150 | H13: =SUM(C13:G13) -> 2190
B14: Parking Fees | C14: 960 | D14: 1080 | E14: 1080 | F14: 1200 | G14: 300 | H14: =SUM(C14:G14) -> 4620
B15: EFFECTIVE GROSS INCOME (EGI) | C15: =SUM(C6:C14) -> 108696 | D15: =SUM(D6:D14) -> 124596 | E15: =SUM(E6:E14) -> 133440 | F15: =SUM(F6:F14) -> 142008 | G15: =SUM(G6:G14) -> 36318 | H15: =SUM(H6:H14) -> 545058
B16: OPERATING EXPENSES
B17: Property Management Fee (8%) | C17: -8640 | D17: -9936 | E17: -10560 | F17: -11088 | G17: -2754 | H17: =SUM(C17:G17) -> -42978
B18: Property Taxes | C18: -14400 | D18: -15120 | E18: -15876 | F18: -16669 | G18: -4167 | H18: =SUM(C18:G18) -> -66232
B19: Insurance (Hazard + Liability) | C19: -4800 | D19: -5040 | E19: -5292 | F19: -5557 | G19: -1389 | H19: =SUM(C19:G19) -> -22078
B20: Water / Sewer | C20: -6480 | D20: -6804 | E20: -7144 | F20: -7501 | G20: -1875 | H20: =SUM(C20:G20) -> -29804
B21: Electric (Common Areas) | C21: -1800 | D21: -1890 | E21: -1985 | F21: -2084 | G21: -521 | H21: =SUM(C21:G21) -> -8280
B22: Landscaping / Snow Removal | C22: -2400 | D22: -2520 | E22: -2646 | F22: -2778 | G22: -695 | H22: =SUM(C22:G22) -> -11039
B23: Repairs & Maintenance | C23: -7200 | D23: -6000 | E23: -9600 | F23: -12000 | G23: -2400 | H23: =SUM(C23:G23) -> -37200
B24: Capital Improvements | C24: -5000 | D24: -3200 | E24: -18000 | F24: -6500 | G24: 0 | H24: =SUM(C24:G24) -> -32700
B25: Trash Removal | C25: -1440 | D25: -1512 | E25: -1588 | F25: -1667 | G25: -417 | H25: =SUM(C25:G25) -> -6624
B26: Pest Control | C26: -960 | D26: -1008 | E26: -1058 | F26: -1111 | G26: -278 | H26: =SUM(C26:G26) -> -4415
B27: Accounting / Admin | C27: -1200 | D27: -1200 | E27: -1200 | F27: -1200 | G27: -300 | H27: =SUM(C27:G27) -> -5100
B28: Vacancy Turnover Costs | C28: -3600 | D28: -2400 | E28: -1800 | F28: -1200 | G28: -400 | H28: =SUM(C28:G28) -> -9400
B29: Reserve Contributions | C29: -3360 | D29: -3528 | E29: -3704 | F29: -3890 | G29: -972 | H29: =SUM(C29:G29) -> -15454
B30: TOTAL OPERATING EXPENSES | C30: =SUM(C17:C29) -> -61280 | D30: =SUM(D17:D29) -> -60158 | E30: =SUM(E17:E29) -> -80453 | F30: =SUM(F17:F29) -> -73245 | G30: =SUM(G17:G29) -> -16168 | H30: =SUM(H17:H29) -> -291304
B31: NET OPERATING INCOME (NOI) | C31: =C15+C30 -> 47416 | D31: =D15+D30 -> 64438 | E31: =E15+E30 -> 52987 | F31: =F15+F30 -> 68763 | G31: =G15+G30 -> 20150 | H31: =H15+H30 -> 253754
B32: Annual Debt Service (P&I) | C32: =-'🏢 Acquisition'!C37*9 -> -54789.805 | D32: =-'🏢 Acquisition'!C37*12 -> -73053.074 | E32: =-'🏢 Acquisition'!C37*12 -> -73053.074 | F32: =-'🏢 Acquisition'!C37*12 -> -73053.074 | G32: =-'🏢 Acquisition'!C37*3 -> -18263.268 | H32: =SUM(C32:G32) -> -292212.3
B33: CASH FLOW BEFORE TAX (CFBT) | C33: =C31+C32 -> -7373.8054 | D33: =D31+D32 -> -8615.0738 | E33: =E31+E32 -> -20066.074 | F33: =F31+F32 -> -4290.0738 | G33: =G31+G32 -> 1886.7315 | H33: =H31+H32 -> -38458.295
B34: OCCUPANCY & OPERATING METRICS
B35: Physical Occupancy Rate | C35: 0.934 | D35: 0.943 | E35: 0.953 | F35: 0.962 | G35: 0.969 | H35: =AVERAGE(C35:G35) -> 0.9522
B36: Economic Occupancy Rate | C36: 0.912 | D36: 0.938 | E36: 0.947 | F36: 0.957 | G36: 0.964 | H36: =AVERAGE(C36:G36) -> 0.9436
B37: Average Monthly Rent / Unit | C37: 1053 | D37: 1165 | E37: 1233 | F37: 1294 | G37: 1325 | H37: =AVERAGE(C37:G37) -> 1214
B38: Operating Expense Ratio (OER) | C38: =IF(C15=0,0,-C30/C15) -> 0.5637742 | D38: =IF(D15=0,0,-D30/D15) -> 0.48282449 | E38: =IF(E15=0,0,-E30/E15) -> 0.60291517 | F38: =IF(F15=0,0,-F30/F15) -> 0.5157808 | G38: =IF(G15=0,0,-G30/G15) -> 0.4451787 | H38: =IF(H15=0,0,-H30/H15) -> 0.53444588

Sheet 🏦 Bank Reconciliation
B1: 🏦 BANK RECONCILIATION — MANAGEMENT vs. BANK
B2: Match management report distributions to bank deposits | Variance must = $0.00 for clean books
B4: SELECT YEAR FOR RECONCILIATION: | E4: 2024
B6: 2024 MONTHLY RECONCILIATION — ALL 14 UNITS
B7: Mo. | C7: Month | D7: Mgmt Report Gross Collections | E7: Mgmt Fees & Expenses Paid | F7: Net Owner Distribution (Rpt) | G7: Bank Deposit Actual | H7: Variance (Must = $0)
B8: 1 | C8: January | D8: 12120 | E8: 1702 | F8: =D8-E8 -> 10418 | G8: 10418 | H8: =G8-F8 -> 0
B9: 2 | C9: February | D9: 12120 | E9: 1694 | F9: =D9-E9 -> 10426 | G9: 10426 | H9: =G9-F9 -> 0
B10: 3 | C10: March | D10: 12120 | E10: 1718 | F10: =D10-E10 -> 10402 | G10: 10402 | H10: =G10-F10 -> 0
B11: 4 | C11: April | D11: 12240 | E11: 1699 | F11: =D11-E11 -> 10541 | G11: 10541 | H11: =G11-F11 -> 0
B12: 5 | C12: May | D12: 12240 | E12: 1712 | F12: =D12-E12 -> 10528 | G12: 10528 | H12: =G12-F12 -> 0
B13: 6 | C13: June | D13: 12120 | E13: 1830 | F13: =D13-E13 -> 10290 | G13: 10290 | H13: =G13-F13 -> 0
B14: 7 | C14: July | D14: 12240 | E14: 1699 | F14: =D14-E14 -> 10541 | G14: 10541 | H14: =G14-F14 -> 0
B15: 8 | C15: August | D15: 12360 | E15: 1708 | F15: =D15-E15 -> 10652 | G15: 10652 | H15: =G15-F15 -> 0
B16: 9 | C16: September | D16: 12360 | E16: 1725 | F16: =D16-E16 -> 10635 | G16: 10635 | H16: =G16-F16 -> 0
B17: 10 | C17: October | D17: 12480 | E17: 1699 | F17: =D17-E17 -> 10781 | G17: 10781 | H17: =G17-F17 -> 0
B18: 11 | C18: November | D18: 12480 | E18: 1714 | F18: =D18-E18 -> 10766 | G18: 10766 | H18: =G18-F18 -> 0
B19: 12 | C19: December | D19: 12480 | E19: 2180 | F19: =D19-E19 -> 10300 | G19: 10300 | H19: =G19-F19 -> 0
B20: 12 | C20: ANNUAL TOTAL | D20: =SUM(D8:D19) -> 147360 | E20: =SUM(E8:E19) -> 21080 | F20: =SUM(F8:F19) -> 126280 | G20: =SUM(G8:G19) -> 126280 | H20: =SUM(H8:H19) -> 0
B22: RECONCILIATION SUMMARY & AUDIT FLAGS
B23: Check | C23: Description | D23: Expected | E23: Actual | F23: Variance | G23: Status
B24: 1 | C24: Annual Distribution Match | D24: =G20 -> 126280 | E24: =F20 -> 126280 | F24: =D24-E24 -> 0 | G24: =IF(ABS(F24)<1,"✅ CLEAN","🔴 REVIEW") -> ✅ CLEAN
B25: 2 | C25: Mgmt Fee % vs Contract (8%) | D25: =D20*0.08 -> 11788.8 | E25: =E20 -> 21080 | F25: =D25-E25 -> -9291.2 | G25: =IF(ABS(F25)<2,"✅ CLEAN","🔴 REVIEW") -> 🔴 REVIEW
B26: 3 | C26: Total Variance = $0 | D26: 0 | E26: =H20 -> 0 | F26: =H20 -> 0 | G26: =IF(ABS(F26)<1,"✅ CLEAN","🔴 REVIEW") -> ✅ CLEAN

Sheet 💰 Return Analysis
B1: 💰 TOTAL RETURN ANALYSIS
B2: Comprehensive return metrics from acquisition date to today | Leveraged & Unleveraged
B4: CURRENT VALUATION ASSUMPTIONS
B5: Estimated Current Market Value | C5: 1970000 | D5: Based on comparable sales / broker opinion
B6: Estimated Selling Costs | C6: 0.06 | D6: 6% of sale price (agent + closing)
B7: Net Proceeds if Sold Today | C7: =C5*(1-C6) -> 1851800 | D7: Before loan payoff
B8: Current Loan Balance (approx.) | C8: =C5*0 -> 0 | D8: Use loan amortization schedule — enter below
B9: Remaining Loan Balance | C9: 1168240 | D9: From lender statement / amortization
B10: Net Equity if Sold Today | C10: =C7-C9 -> 683560 | D10: Net proceeds minus loan payoff
B11: Original Equity Invested | C11: ='🏢 Acquisition'!C39 -> 472762 | D11: From closing
B13: KEY RETURN METRICS
B14: Metric | C14: Value | D14: Definition / Notes
B15: ── INCOME RETURNS ──
B16: Going-In Cap Rate (2021 NOI) | C16: ='📈 Operating History'!C31/'🏢 Acquisition'!C16 -> 0.02873697 | D16: NOI Year 1 ÷ Purchase Price
B17: Current Cap Rate (2024 NOI) | C17: ='📈 Operating History'!F31/C5 -> 0.034905076 | D17: 2024 NOI ÷ Current Market Value
B18: Stabilized NOI (2024) | C18: ='📈 Operating History'!F31 -> 68763 | D18: Net Operating Income before debt service
B19: Debt Service Coverage (2024) | C19: =IF('🏢 Acquisition'!C38=0,0,'📈 Operating History'!F31/'🏢 Acquisition'!C38) -> 0.94127456 | D19: NOI ÷ Annual Debt Service (>1.20x healthy)
B20: ── CASH-ON-CASH RETURNS ──
B21: CoC Return — Year 1 (2021) | C21: ='📈 Operating History'!C33/'🏢 Acquisition'!C39 -> -0.015597289 | D21: CFBT ÷ Equity Invested (partial year)
B22: CoC Return — Year 2 (2022) | C22: ='📈 Operating History'!D33/'🏢 Acquisition'!C39 -> -0.018222856 | D22: CFBT ÷ Equity Invested
B23: CoC Return — Year 3 (2023) | C23: ='📈 Operating History'!E33/'🏢 Acquisition'!C39 -> -0.042444346 | D23: CFBT ÷ Equity Invested
B24: CoC Return — Year 4 (2024) | C24: ='📈 Operating History'!F33/'🏢 Acquisition'!C39 -> -0.0090744895 | D24: CFBT ÷ Equity Invested
B25: ── TOTAL RETURN METRICS ──
B26: Total Cash Flow Received | C26: ='📈 Operating History'!H33 -> -38458.295 | D26: Cumulative CFBT since acquisition
B27: Unrealized Appreciation | C27: =C5-'🏢 Acquisition'!C16 -> 320000 | D27: Current value minus purchase price
B28: Principal Paydown (Equity Buildup) | C28: ='🏢 Acquisition'!C33-C9 -> 69260 | D28: Original loan minus current balance
B29: Total Wealth Created | C29: =C26+C27+C28 -> 350801.7 | D29: Cash flow + appreciation + equity buildup
B30: Equity Multiple (Total) | C30: =IF(C11=0,0,(C11+C29)/C11) -> 1.742026 | D30: (Equity + total returns) ÷ equity invested
B31: Annualized Return (Simple) | C31: =IF(C11=0,0,C29/C11/'🏢 Acquisition'!C10) -> 0.18945345 | D31: Total return ÷ equity ÷ years held
B32: ── GROSS RENT MULTIPLIER ──
B33: Going-In GRM | C33: ='🏢 Acquisition'!C16/'📈 Operating History'!C15 -> 15.179951 | D33: Purchase Price ÷ Year 1 Gross Income
B34: Current GRM | C34: =C5/'📈 Operating History'!F15 -> 13.872458 | D34: Current Value ÷ 2024 Gross Income
B35: Price / Unit (Acquisition) | C35: ='🏢 Acquisition'!C16/14 -> 117857.14 | D35: Purchase price per unit
B36: Price / Unit (Current Est.) | C36: =C5/14 -> 140714.29 | D36: Current value per unit
B39: CASH FLOW SCHEDULE FOR IRR CALCULATION
B40: Period | C40: Cash Flow | D40: Notes
B41: 2021-03-15 (Acquisition) | C41: =-'🏢 Acquisition'!C39 -> -472762 | D41: Initial equity outflow
B42: 2021 (partial year CFBT) | C42: ='📈 Operating History'!C33 -> -7373.8054 | D42: 9 months operations
B43: 2022 CFBT | C43: ='📈 Operating History'!D33 -> -8615.0738 | D43: Full year
B44: 2023 CFBT | C44: ='📈 Operating History'!E33 -> -20066.074 | D44: Full year
...

Sheet 📋 Instructions
B1: 📋 ANALYST INSTRUCTIONS & DATA ENTRY GUIDE
B2: Complete workflow for matching closing statement, management reports, and bank records to calculated returns
B4: HOW TO USE THIS MODEL
B5: STEP 1 — Acquisition Tab | C5: Enter all figures from your HUD-1/ALTA closing statement. Blue cells only. Verify loan amount, rate, and equity invested.
B6: STEP 2 — Operating History | C6: Transfer annual totals from management company statements, year by year. Each column = one calendar year.
B7: STEP 3 — Bank Reconciliation | C7: For each month, enter (a) gross collections per management report, (b) fees/expenses they retained, and (c) the actual bank deposit. Variance should = $0.
B8: STEP 4 — Return Analysis | C8: Enter current estimated market value and current loan balance. All metrics calculate automatically.
B9: STEP 5 — Dashboard | C9: Review the complete picture. Share this tab with investors or partners.
B11: COLOR CODING
B12: Blue text / light blue cell | C12: YOUR INPUT — enter data from source documents here
B13: Black text / white cell | C13: FORMULA — auto-calculated, do not overwrite
B14: Green text | C14: CROSS-SHEET LINK — pulling from another tab
B16: KEY METRICS DEFINED
B17: Cap Rate | C17: NOI ÷ Property Value. Measures property income yield independent of financing.
B18: Cash-on-Cash (CoC) | C18: Annual CFBT ÷ Equity Invested. Measures annual cash yield on your equity.
B19: DSCR | C19: NOI ÷ Annual Debt Service. >1.25x = strong; <1.0x = cash flow negative.
B20: Equity Multiple | C20: Total return ÷ equity invested. 2.0x means you doubled your money.
B21: IRR | C21: Annualized time-weighted return accounting for timing of all cash flows.
B22: GRM | C22: Purchase Price ÷ Gross Annual Income. Lower is better (paid less per $ of rent).
B23: Bank Rec Variance | C23: Management distribution per report minus actual bank deposit. Must = $0.00 for clean books.
