Workbook

Sheet Cover
B8: SaaS Financial Plan
B9: Enterprise Edition · Multi-Tier · Full 3-Statement Model
B10: Built by Quanthaven Labs LLC
B12: ✓ 3-Tier Pricing (Starter / Growth / Enterprise)
B14: ✓ Acquisition Funnel (Organic / Paid / Partner channels)
B16: ✓ Annual vs. Monthly Billing + Deferred Revenue
B18: ✓ Full 3-Statement Model (P&L · Balance Sheet · Cash Flow)
B20: ✓ SaaS KPI Dashboard with Benchmark Flags
B22: ✓ Scenario Toggle (Base / Upside / Downside)
B24: ✓ Burn Rate & Runway Tracker
B26: ✓ 36-Month Rolling Forecast (3 Years)
B31: ="Version 1.0 · Model Start: "&TEXT(Controls!$B$6,"mmmm yyyy")&" · Forecast Horizon: 36 Months" -> Version 1.0 · Model Start: January 2026 · Forecast Horizon: 36 Months
B33: START HERE → Controls → Revenue → Headcount → OpEx → P&L · Balance Sheet · Cash Flow · KPI Dashboard

Sheet Instructions
A2: HOW TO USE THIS MODEL · Step-by-Step Guide
A4: 1 | B4: Controls Tab | C4: Start here. Set your tax rate, scenario (Base/Upside/Downside), opening cash balance, payroll tax rate, and benefits rate. These feed the entire model.
A6: 2 | B6: Revenue Tab – Pricing | C6: Enter your ARPU for each tier (Starter / Growth / Enterprise) and the % of customers expected to choose annual billing per tier.
A8: 3 | B8: Revenue Tab – Acquisition Funnel | C8: Set Month 1 website visitors and traffic growth rate. Set trial and conversion rates. Set Month 1 paid marketing budget, CAC, partner leads, and close rate. The model computes monthly new customers from all three channels.
A10: 4 | B10: Revenue Tab – Customer Mix & Churn | C10: Set the % of new customers going to each tier (must sum to 100%). Set monthly gross churn rates per tier. Expansion MRR rates are pre-filled — adjust as needed.
A12: 5 | B12: Revenue Tab – Services Revenue | C12: Row 104: Pre-filled monthly professional services revenue. Overwrite with your own actuals or projections.
A14: 6 | B14: Headcount Tab | C14: Enter monthly base salary cost by department. Benefits and payroll tax are applied automatically from your Controls assumptions.
A16: 7 | B16: OpEx Tab | C16: Enter non-wage operating expenses by department and category. Categories are pre-filled with reasonable starting assumptions — adjust to match your cost structure.
A18: 8 | B18: P&L Tab | C18: Read-only (calculated). Review your SaaS income statement: Subscription revenue, COGS, Gross Profit, EBITDA, EBIT, and Net Income with margin percentages.
A20: 9 | B20: Balance Sheet Tab | C20: Read-only (calculated). End-of-period balance sheet. Review assets (cash, AR), liabilities (AP, deferred revenue), and equity.
A22: 10 | B22: Cash Flow Tab | C22: Read-only (calculated). Indirect-method cash flow statement. Monitor FCF, monthly burn rate, and runway in months.
A24: 11 | B24: KPI Dashboard | C24: Read-only (calculated). All key SaaS metrics: MRR, ARR, NRR, Gross Margin, EBITDA, ARPA, LTV, CAC, LTV:CAC, CAC Payback, Magic Number, Rule of 40. Benchmark reference guide included.
A26: 12 | B26: Scenario Analysis | C26: Change the "Active Scenario" in Controls!B12 between Base, Upside, and Downside. The revenue multiplier and churn multiplier are applied automatically. Compare outputs in the KPI Dashboard.

Sheet Controls
A1: GLOBAL CONTROLS
A2: All blue cells below are user inputs — changes flow through the entire model
A3: Setting | B3: Value | C3: Notes
A5: MODEL SETTINGS
A6: Model Start Date | B6: 46023 | C6: Enter as an actual date — Excel will display as mmm-yy (e.g. Jan-25). All headers auto-update.
A7: Forecast Horizon (Months) | B7: 36 | C7: Active months: 12–60. Columns beyond this show gray/zero. Annual cols auto-adjust.
A8: Tax Rate | B8: 0.25 | C8: Effective corp income tax rate
A9: Base Currency | B9: USD
A10: SCENARIO TOGGLE
A11: Scenario Instructions | C11: Type "Base", "Upside", or "Downside" in B12
A12: Active Scenario | B12: Base | C12: Base | Upside | Downside
A13: Upside Rev Multiplier | B13: 1.25 | C13: Applied to new customer counts
A14: Downside Rev Multiplier | B14: 0.75 | C14: Applied to new customer counts
A15: Upside Churn Multiplier | B15: 0.8 | C15: Lower churn in upside (e.g. 0.80 = 20% better)
A16: Downside Churn Multiplier | B16: 1.3 | C16: Higher churn in downside (e.g. 1.30 = 30% worse)
A17: FINANCING
A18: Financing Instructions | C18: Enter opening cash balance and any debt raised at model start
A19: Opening Cash Balance ($) | B19: 1000000 | C19: Cash on hand at model start (seed / Series A proceeds)
A20: Debt Raised ($) | B20: 0 | C20: Term loan or convertible note principal
A21: Annual Interest Rate | B21: 0.08 | C21: Interest on outstanding debt
A22: EXPENSE ASSUMPTIONS
A23: Expense Instructions | C23: These rates are applied globally in Headcount tab
A24: Employer Payroll Tax Rate | B24: 0.0765 | C24: Federal FICA — adjust for state
A25: Benefits Rate (% Salary) | B25: 0.18 | C25: Health, dental, vision, 401k match
A26: CapEx Depr Life (Years) | B26: 3 | C26: Straight-line useful life for CapEx
A29: COLOR KEY
A30: Sample Text | B30: Blue text on yellow → User input — safe to change
A31: Sample Text | B31: Black text → Formula — do not manually overwrite
A32: Sample Text | B32: Green text → Linked from another tab
A33: Sample Text | B33: Gray italic → Descriptive label or instruction

Sheet Revenue
A1: REVENUE MODEL · 3-Tier SaaS Subscription + Acquisition Funnel
A3: Label | B3: Unit | C3: =TEXT(EDATE(Controls!$B$6,0),"mmm-yy") -> Jan-26 | D3: =TEXT(EDATE(Controls!$B$6,1),"mmm-yy") -> Feb-26 | E3: =TEXT(EDATE(Controls!$B$6,2),"mmm-yy") -> Mar-26 | F3: =TEXT(EDATE(Controls!$B$6,3),"mmm-yy") -> Apr-26 | G3: =TEXT(EDATE(Controls!$B$6,4),"mmm-yy") -> May-26 | H3: =TEXT(EDATE(Controls!$B$6,5),"mmm-yy") -> Jun-26 | I3: =TEXT(EDATE(Controls!$B$6,6),"mmm-yy") -> Jul-26 | J3: =TEXT(EDATE(Controls!$B$6,7),"mmm-yy") -> Aug-26 | K3: =TEXT(EDATE(Controls!$B$6,8),"mmm-yy") -> Sep-26 | L3: =TEXT(EDATE(Controls!$B$6,9),"mmm-yy") -> Oct-26 | M3: =TEXT(EDATE(Controls!$B$6,10),"mmm-yy") -> Nov-26 | N3: =TEXT(EDATE(Controls!$B$6,11),"mmm-yy") -> Dec-26 | O3: =TEXT(EDATE(Controls!$B$6,12),"mmm-yy") -> Jan-27 | P3: =TEXT(EDATE(Controls!$B$6,13),"mmm-yy") -> Feb-27 | Q3: =TEXT(EDATE(Controls!$B$6,14),"mmm-yy") -> Mar-27 | R3: =TEXT(EDATE(Controls!$B$6,15),"mmm-yy") -> Apr-27 | S3: =TEXT(EDATE(Controls!$B$6,16),"mmm-yy") -> May-27 | T3: =TEXT(EDATE(Controls!$B$6,17),"mmm-yy") -> Jun-27 | U3: =TEXT(EDATE(Controls!$B$6,18),"mmm-yy") -> Jul-27 | V3: =TEXT(EDATE(Controls!$B$6,19),"mmm-yy") -> Aug-27 | W3: =TEXT(EDATE(Controls!$B$6,20),"mmm-yy") -> Sep-27 | X3: =TEXT(EDATE(Controls!$B$6,21),"mmm-yy") -> Oct-27 | Y3: =TEXT(EDATE(Controls!$B$6,22),"mmm-yy") -> Nov-27 | Z3: =TEXT(EDATE(Controls!$B$6,23),"mmm-yy") -> Dec-27 | AA3: =TEXT(EDATE(Controls!$B$6,24),"mmm-yy") -> Jan-28 | AB3: =TEXT(EDATE(Controls!$B$6,25),"mmm-yy") -> Feb-28 | AC3: =TEXT(EDATE(Controls!$B$6,26),"mmm-yy") -> Mar-28 | AD3: =TEXT(EDATE(Controls!$B$6,27),"mmm-yy") -> Apr-28 | AE3: =TEXT(EDATE(Controls!$B$6,28),"mmm-yy") -> May-28 | AF3: =TEXT(EDATE(Controls!$B$6,29),"mmm-yy") -> Jun-28 | AG3: =TEXT(EDATE(Controls!$B$6,30),"mmm-yy") -> Jul-28 | AH3: =TEXT(EDATE(Controls!$B$6,31),"mmm-yy") -> Aug-28 | AI3: =TEXT(EDATE(Controls!$B$6,32),"mmm-yy") -> Sep-28 | AJ3: =TEXT(EDATE(Controls!$B$6,33),"mmm-yy") -> Oct-28 | AK3: =TEXT(EDATE(Controls!$B$6,34),"mmm-yy") -> Nov-28 | AL3: =TEXT(EDATE(Controls!$B$6,35),"mmm-yy") -> Dec-28 | AM3: =TEXT(EDATE(Controls!$B$6,36),"mmm-yy") -> Jan-29 | AN3: =TEXT(EDATE(Controls!$B$6,37),"mmm-yy") -> Feb-29 | AO3: =TEXT(EDATE(Controls!$B$6,38),"mmm-yy") -> Mar-29 | AP3: =TEXT(EDATE(Controls!$B$6,39),"mmm-yy") -> Apr-29 | AQ3: =TEXT(EDATE(Controls!$B$6,40),"mmm-yy") -> May-29 | AR3: =TEXT(EDATE(Controls!$B$6,41),"mmm-yy") -> Jun-29 | AS3: =TEXT(EDATE(Controls!$B$6,42),"mmm-yy") -> Jul-29 | AT3: =TEXT(EDATE(Controls!$B$6,43),"mmm-yy") -> Aug-29 | AU3: =TEXT(EDATE(Controls!$B$6,44),"mmm-yy") -> Sep-29 | AV3: =TEXT(EDATE(Controls!$B$6,45),"mmm-yy") -> Oct-29 | AW3: =TEXT(EDATE(Controls!$B$6,46),"mmm-yy") -> Nov-29 | AX3: =TEXT(EDATE(Controls!$B$6,47),"mmm-yy") -> Dec-29 | AY3: =TEXT(EDATE(Controls!$B$6,48),"mmm-yy") -> Jan-30 | AZ3: =TEXT(EDATE(Controls!$B$6,49),"mmm-yy") -> Feb-30 | BA3: =TEXT(EDATE(Controls!$B$6,50),"mmm-yy") -> Mar-30 | BB3: =TEXT(EDATE(Controls!$B$6,51),"mmm-yy") -> Apr-30 | BC3: =TEXT(EDATE(Controls!$B$6,52),"mmm-yy") -> May-30 | BD3: =TEXT(EDATE(Controls!$B$6,53),"mmm-yy") -> Jun-30 | BE3: =TEXT(EDATE(Controls!$B$6,54),"mmm-yy") -> Jul-30 | BF3: =TEXT(EDATE(Controls!$B$6,55),"mmm-yy") -> Aug-30 | BG3: =TEXT(EDATE(Controls!$B$6,56),"mmm-yy") -> Sep-30 | BH3: =TEXT(EDATE(Controls!$B$6,57),"mmm-yy") -> Oct-30 | BI3: =TEXT(EDATE(Controls!$B$6,58),"mmm-yy") -> Nov-30 | BJ3: =TEXT(EDATE(Controls!$B$6,59),"mmm-yy") -> Dec-30 | BK3: ="FY "&(YEAR(Controls!$B$6)+0) -> FY 2026 | BL3: ="FY "&(YEAR(Controls!$B$6)+1) -> FY 2027 | BM3: ="FY "&(YEAR(Controls!$B$6)+2) -> FY 2028 | BN3: ="FY "&(YEAR(Controls!$B$6)+3) -> FY 2029 | BO3: ="FY "&(YEAR(Controls!$B$6)+4) -> FY 2030 | BP3: ="FY "&(YEAR(Controls!$B$6)+5) -> FY 2031
A5: PRICING ASSUMPTIONS
A6: Starter ARPU (Monthly) | B6: $/mo | C6: 49 | D6: ← Single-cell inputs (col C). Copy right if you want tier-specific monthly variation.
A7: Growth ARPU (Monthly) | B7: $/mo | C7: 149
A8: Enterprise ARPU (Monthly) | B8: $/mo | C8: 499
A9: % on Annual Plan – Starter | B9: % | C9: 0.2
A10: % on Annual Plan – Growth | B10: % | C10: 0.35
A11: % on Annual Plan – Enterprise | B11: % | C11: 0.6
A13: ACQUISITION FUNNEL · Organic / Paid / Partner
A14: Organic Channel
A15: Month 1 Website Visitors (Input) | B15: # | C15: 5000
A16: MoM Traffic Growth Rate | B16: % | C16: 0.05
A17: Monthly Website Visitors | B17: # | C17: =C15 -> 5000 | D17: =IF(COLUMN()-2<=Controls!$B$7,C17*(1+$C$16),0) -> 5250 | E17: =IF(COLUMN()-2<=Controls!$B$7,D17*(1+$C$16),0) -> 5512.5 | F17: =IF(COLUMN()-2<=Controls!$B$7,E17*(1+$C$16),0) -> 5788.125 | G17: =IF(COLUMN()-2<=Controls!$B$7,F17*(1+$C$16),0) -> 6077.5312 | H17: =IF(COLUMN()-2<=Controls!$B$7,G17*(1+$C$16),0) -> 6381.4078 | I17: =IF(COLUMN()-2<=Controls!$B$7,H17*(1+$C$16),0) -> 6700.4782 | J17: =IF(COLUMN()-2<=Controls!$B$7,I17*(1+$C$16),0) -> 7035.5021 | K17: =IF(COLUMN()-2<=Controls!$B$7,J17*(1+$C$16),0) -> 7387.2772 | ... BJ17: =IF(COLUMN()-2<=Controls!$B$7,BI17*(1+$C$16),0) -> 0 | BK17: =SUMPRODUCT((YEAR(EDATE(Controls!$B$6,COLUMN($C$1:$BJ$1)-COLUMN($C$1)))=YEAR(Controls!$B$6)+0)*(COLUMN($C$1:$BJ$1)-COLUMN($C$1)<Controls!$B$7)*$C$17:$BJ$17) -> 79585.633 | BL17: =SUMPRODUCT((YEAR(EDATE(Controls!$B$6,COLUMN($C$1:$BJ$1)-COLUMN($C$1)))=YEAR(Controls!$B$6)+1)*(COLUMN($C$1:$BJ$1)-COLUMN($C$1)<Controls!$B$7)*$C$17:$BJ$17) -> 142924.36 | BM17: =SUMPRODUCT((YEAR(EDATE(Controls!$B$6,COLUMN($C$1:$BJ$1)-COLUMN($C$1)))=YEAR(Controls!$B$6)+2)*(COLUMN($C$1:$BJ$1)-COLUMN($C$1)<Controls!$B$7)*$C$17:$BJ$17) -> 256671.62 | BN17: =SUMPRODUCT((YEAR(EDATE(Controls!$B$6,COLUMN($C$1:$BJ$1)-COLUMN($C$1)))=YEAR(Controls!$B$6)+3)*(COLUMN($C$1:$BJ$1)-COLUMN($C$1)<Controls!$B$7)*$C$17:$BJ$17) -> 0 | BO17: =SUMPRODUCT((YEAR(EDATE(Controls!$B$6,COLUMN($C$1:$BJ$1)-COLUMN($C$1)))=YEAR(Controls!$B$6)+4)*(COLUMN($C$1:$BJ$1)-COLUMN($C$1)<Controls!$B$7)*$C$17:$BJ$17) -> 0 | BP17: =SUMPRODUCT((YEAR(EDATE(Controls!$B$6,COLUMN($C$1:$BJ$1)-COLUMN($C$1)))=YEAR(Controls!$B$6)+5)*(COLUMN($C$1:$BJ$1)-COLUMN($C$1)<Controls!$B$7)*$C$17:$BJ$17) -> 0
A18: Trial Sign-Up Rate | B18: % | C18: 0.03
A19: Trial-to-Paid Conversion | B19: % | C19: 0.25
A20: New Customers – Organic | B20: # | C20: =ROUND(C17*$C$18*$C$19,0) -> 38 | D20: =ROUND(D17*$C$18*$C$19,0) -> 39 | E20: =ROUND(E17*$C$18*$C$19,0) -> 41 | F20: =ROUND(F17*$C$18*$C$19,0) -> 43 | G20: =ROUND(G17*$C$18*$C$19,0) -> 46 | H20: =ROUND(H17*$C$18*$C$19,0) -> 48 | I20: =ROUND(I17*$C$18*$C$19,0) -> 50 | J20: =ROUND(J17*$C$18*$C$19,0) -> 53 | ... BJ20: =ROUND(BJ17*$C$18*$C$19,0) -> 0 | BK20: =SUMPRODUCT((YEAR(EDATE(Controls!$B$6,COLUMN($C$1:$BJ$1)-COLUMN($C$1)))=YEAR(Controls!$B$6)+0)*(COLUMN($C$1:$BJ$1)-COLUMN($C$1)<Controls!$B$7)*$C$20:$BJ$20) -> 596 | BL20: =SUMPRODUCT((YEAR(EDATE(Controls!$B$6,COLUMN($C$1:$BJ$1)-COLUMN($C$1)))=YEAR(Controls!$B$6)+1)*(COLUMN($C$1:$BJ$1)-COLUMN($C$1)<Controls!$B$7)*$C$20:$BJ$20) -> 1071 | BM20: =SUMPRODUCT((YEAR(EDATE(Controls!$B$6,COLUMN($C$1:$BJ$1)-COLUMN($C$1)))=YEAR(Controls!$B$6)+2)*(COLUMN($C$1:$BJ$1)-COLUMN($C$1)<Controls!$B$7)*$C$20:$BJ$20) -> 1925 | BN20: =SUMPRODUCT((YEAR(EDATE(Controls!$B$6,COLUMN($C$1:$BJ$1)-COLUMN($C$1)))=YEAR(Controls!$B$6)+3)*(COLUMN($C$1:$BJ$1)-COLUMN($C$1)<Controls!$B$7)*$C$20:$BJ$20) -> 0 | BO20: =SUMPRODUCT((YEAR(EDATE(Controls!$B$6,COLUMN($C$1:$BJ$1)-COLUMN($C$1)))=YEAR(Controls!$B$6)+4)*(COLUMN($C$1:$BJ$1)-COLUMN($C$1)<Controls!$B$7)*$C$20:$BJ$20) -> 0 | BP20: =SUMPRODUCT((YEAR(EDATE(Controls!$B$6,COLUMN($C$1:$BJ$1)-COLUMN($C$1)))=YEAR(Controls!$B$6)+5)*(COLUMN($C$1:$BJ$1)-COLUMN($C$1)<Controls!$B$7)*$C$20:$BJ$20) -> 0
A22: Paid Channel
A23: Month 1 Paid Marketing Budget | B23: $ | C23: 10000
A24: MoM Budget Growth Rate | B24: % | C24: 0.08
A25: Monthly Paid Budget | B25: $ | C25: =C23 -> 10000 | D25: =IF(COLUMN()-2<=Controls!$B$7,C25*(1+$C$24),0) -> 10800 | E25: =IF(COLUMN()-2<=Controls!$B$7,D25*(1+$C$24),0) -> 11664 | F25: =IF(COLUMN()-2<=Controls!$B$7,E25*(1+$C$24),0) -> 12597.12 | G25: =IF(COLUMN()-2<=Controls!$B$7,F25*(1+$C$24),0) -> 13604.89 | H25: =IF(COLUMN()-2<=Controls!$B$7,G25*(1+$C$24),0) -> 14693.281 | I25: =IF(COLUMN()-2<=Controls!$B$7,H25*(1+$C$24),0) -> 15868.743 | J25: =IF(COLUMN()-2<=Controls!$B$7,I25*(1+$C$24),0) -> 17138.243 | K25: =IF(COLUMN()-2<=Controls!$B$7,J25*(1+$C$24),0) -> 18509.302 | ... BJ25: =IF(COLUMN()-2<=Controls!$B$7,BI25*(1+$C$24),0) -> 0 | BK25: =SUMPRODUCT((YEAR(EDATE(Controls!$B$6,COLUMN($C$1:$BJ$1)-COLUMN($C$1)))=YEAR(Controls!$B$6)+0)*(COLUMN($C$1:$BJ$1)-COLUMN($C$1)<Controls!$B$7)*$C$25:$BJ$25) -> 189771.26 | BL25: =SUMPRODUCT((YEAR(EDATE(Controls!$B$6,COLUMN($C$1:$BJ$1)-COLUMN($C$1)))=YEAR(Controls!$B$6)+1)*(COLUMN($C$1:$BJ$1)-COLUMN($C$1)<Controls!$B$7)*$C$25:$BJ$25) -> 477876.33 | BM25: =SUMPRODUCT((YEAR(EDATE(Controls!$B$6,COLUMN($C$1:$BJ$1)-COLUMN($C$1)))=YEAR(Controls!$B$6)+2)*(COLUMN($C$1:$BJ$1)-COLUMN($C$1)<Controls!$B$7)*$C$25:$BJ$25) -> 1203373.9 | BN25: =SUMPRODUCT((YEAR(EDATE(Controls!$B$6,COLUMN($C$1:$BJ$1)-COLUMN($C$1)))=YEAR(Controls!$B$6)+3)*(COLUMN($C$1:$BJ$1)-COLUMN($C$1)<Controls!$B$7)*$C$25:$BJ$25) -> 0 | BO25: =SUMPRODUCT((YEAR(EDATE(Controls!$B$6,COLUMN($C$1:$BJ$1)-COLUMN($C$1)))=YEAR(Controls!$B$6)+4)*(COLUMN($C$1:$BJ$1)-COLUMN($C$1)<Controls!$B$7)*$C$25:$BJ$25) -> 0 | BP25: =SUMPRODUCT((YEAR(EDATE(Controls!$B$6,COLUMN($C$1:$BJ$1)-COLUMN($C$1)))=YEAR(Controls!$B$6)+5)*(COLUMN($C$1:$BJ$1)-COLUMN($C$1)<Controls!$B$7)*$C$25:$BJ$25) -> 0
A26: Blended Paid CAC | B26: $ | C26: 450
A27: New Customers – Paid | B27: # | C27: =IFERROR(ROUND(C25/$C$26,0),0) -> 22 | D27: =IFERROR(ROUND(D25/$C$26,0),0) -> 24 | E27: =IFERROR(ROUND(E25/$C$26,0),0) -> 26 | F27: =IFERROR(ROUND(F25/$C$26,0),0) -> 28 | G27: =IFERROR(ROUND(G25/$C$26,0),0) -> 30 | H27: =IFERROR(ROUND(H25/$C$26,0),0) -> 33 | I27: =IFERROR(ROUND(I25/$C$26,0),0) -> 35 | J27: =IFERROR(ROUND(J25/$C$26,0),0) -> 38 | ... BJ27: =IFERROR(ROUND(BJ25/$C$26,0),0) -> 0 | BK27: =SUMPRODUCT((YEAR(EDATE(Controls!$B$6,COLUMN($C$1:$BJ$1)-COLUMN($C$1)))=YEAR(Controls!$B$6)+0)*(COLUMN($C$1:$BJ$1)-COLUMN($C$1)<Controls!$B$7)*$C$27:$BJ$27) -> 421 | BL27: =SUMPRODUCT((YEAR(EDATE(Controls!$B$6,COLUMN($C$1:$BJ$1)-COLUMN($C$1)))=YEAR(Controls!$B$6)+1)*(COLUMN($C$1:$BJ$1)-COLUMN($C$1)<Controls!$B$7)*$C$27:$BJ$27) -> 1061 | BM27: =SUMPRODUCT((YEAR(EDATE(Controls!$B$6,COLUMN($C$1:$BJ$1)-COLUMN($C$1)))=YEAR(Controls!$B$6)+2)*(COLUMN($C$1:$BJ$1)-COLUMN($C$1)<Controls!$B$7)*$C$27:$BJ$27) -> 2676 | BN27: =SUMPRODUCT((YEAR(EDATE(Controls!$B$6,COLUMN($C$1:$BJ$1)-COLUMN($C$1)))=YEAR(Controls!$B$6)+3)*(COLUMN($C$1:$BJ$1)-COLUMN($C$1)<Controls!$B$7)*$C$27:$BJ$27) -> 0 | BO27: =SUMPRODUCT((YEAR(EDATE(Controls!$B$6,COLUMN($C$1:$BJ$1)-COLUMN($C$1)))=YEAR(Controls!$B$6)+4)*(COLUMN($C$1:$BJ$1)-COLUMN($C$1)<Controls!$B$7)*$C$27:$BJ$27) -> 0 | BP27: =SUMPRODUCT((YEAR(EDATE(Controls!$B$6,COLUMN($C$1:$BJ$1)-COLUMN($C$1)))=YEAR(Controls!$B$6)+5)*(COLUMN($C$1:$BJ$1)-COLUMN($C$1)<Controls!$B$7)*$C$27:$BJ$27) -> 0
A29: Partner / Referral Channel
A30: Month 1 Partner Leads | B30: # | C30: 15
A31: MoM Leads Growth Rate | B31: % | C31: 0.05
A32: Monthly Partner Leads | B32: # | C32: =C30 -> 15 | D32: =IF(COLUMN()-2<=Controls!$B$7,C32*(1+$C$31),0) -> 15.75 | E32: =IF(COLUMN()-2<=Controls!$B$7,D32*(1+$C$31),0) -> 16.5375 | F32: =IF(COLUMN()-2<=Controls!$B$7,E32*(1+$C$31),0) -> 17.364375 | G32: =IF(COLUMN()-2<=Controls!$B$7,F32*(1+$C$31),0) -> 18.232594 | H32: =IF(COLUMN()-2<=Controls!$B$7,G32*(1+$C$31),0) -> 19.144223 | I32: =IF(COLUMN()-2<=Controls!$B$7,H32*(1+$C$31),0) -> 20.101435 | J32: =IF(COLUMN()-2<=Controls!$B$7,I32*(1+$C$31),0) -> 21.106506 | K32: =IF(COLUMN()-2<=Controls!$B$7,J32*(1+$C$31),0) -> 22.161832 | ... BJ32: =IF(COLUMN()-2<=Controls!$B$7,BI32*(1+$C$31),0) -> 0 | BK32: =SUMPRODUCT((YEAR(EDATE(Controls!$B$6,COLUMN($C$1:$BJ$1)-COLUMN($C$1)))=YEAR(Controls!$B$6)+0)*(COLUMN($C$1:$BJ$1)-COLUMN($C$1)<Controls!$B$7)*$C$32:$BJ$32) -> 238.7569 | BL32: =SUMPRODUCT((YEAR(EDATE(Controls!$B$6,COLUMN($C$1:$BJ$1)-COLUMN($C$1)))=YEAR(Controls!$B$6)+1)*(COLUMN($C$1:$BJ$1)-COLUMN($C$1)<Controls!$B$7)*$C$32:$BJ$32) -> 428.77309 | BM32: =SUMPRODUCT((YEAR(EDATE(Controls!$B$6,COLUMN($C$1:$BJ$1)-COLUMN($C$1)))=YEAR(Controls!$B$6)+2)*(COLUMN($C$1:$BJ$1)-COLUMN($C$1)<Controls!$B$7)*$C$32:$BJ$32) -> 770.01486 | BN32: =SUMPRODUCT((YEAR(EDATE(Controls!$B$6,COLUMN($C$1:$BJ$1)-COLUMN($C$1)))=YEAR(Controls!$B$6)+3)*(COLUMN($C$1:$BJ$1)-COLUMN($C$1)<Controls!$B$7)*$C$32:$BJ$32) -> 0 | BO32: =SUMPRODUCT((YEAR(EDATE(Controls!$B$6,COLUMN($C$1:$BJ$1)-COLUMN($C$1)))=YEAR(Controls!$B$6)+4)*(COLUMN($C$1:$BJ$1)-COLUMN($C$1)<Controls!$B$7)*$C$32:$BJ$32) -> 0 | BP32: =SUMPRODUCT((YEAR(EDATE(Controls!$B$6,COLUMN($C$1:$BJ$1)-COLUMN($C$1)))=YEAR(Controls!$B$6)+5)*(COLUMN($C$1:$BJ$1)-COLUMN($C$1)<Controls!$B$7)*$C$32:$BJ$32) -> 0
A33: Partner Close Rate | B33: % | C33: 0.15
A34: New Customers – Partner | B34: # | C34: =ROUND(C32*$C$33,0) -> 2 | D34: =ROUND(D32*$C$33,0) -> 2 | E34: =ROUND(E32*$C$33,0) -> 2 | F34: =ROUND(F32*$C$33,0) -> 3 | G34: =ROUND(G32*$C$33,0) -> 3 | H34: =ROUND(H32*$C$33,0) -> 3 | I34: =ROUND(I32*$C$33,0) -> 3 | J34: =ROUND(J32*$C$33,0) -> 3 | ... BJ34: =ROUND(BJ32*$C$33,0) -> 0 | BK34: =SUMPRODUCT((YEAR(EDATE(Controls!$B$6,COLUMN($C$1:$BJ$1)-COLUMN($C$1)))=YEAR(Controls!$B$6)+0)*(COLUMN($C$1:$BJ$1)-COLUMN($C$1)<Controls!$B$7)*$C$34:$BJ$34) -> 35 | BL34: =SUMPRODUCT((YEAR(EDATE(Controls!$B$6,COLUMN($C$1:$BJ$1)-COLUMN($C$1)))=YEAR(Controls!$B$6)+1)*(COLUMN($C$1:$BJ$1)-COLUMN($C$1)<Controls!$B$7)*$C$34:$BJ$34) -> 64 | BM34: =SUMPRODUCT((YEAR(EDATE(Controls!$B$6,COLUMN($C$1:$BJ$1)-COLUMN($C$1)))=YEAR(Controls!$B$6)+2)*(COLUMN($C$1:$BJ$1)-COLUMN($C$1)<Controls!$B$7)*$C$34:$BJ$34) -> 115 | BN34: =SUMPRODUCT((YEAR(EDATE(Controls!$B$6,COLUMN($C$1:$BJ$1)-COLUMN($C$1)))=YEAR(Controls!$B$6)+3)*(COLUMN($C$1:$BJ$1)-COLUMN($C$1)<Controls!$B$7)*$C$34:$BJ$34) -> 0 | BO34: =SUMPRODUCT((YEAR(EDATE(Controls!$B$6,COLUMN($C$1:$BJ$1)-COLUMN($C$1)))=YEAR(Controls!$B$6)+4)*(COLUMN($C$1:$BJ$1)-COLUMN($C$1)<Controls!$B$7)*$C$34:$BJ$34) -> 0 | BP34: =SUMPRODUCT((YEAR(EDATE(Controls!$B$6,COLUMN($C$1:$BJ$1)-COLUMN($C$1)))=YEAR(Controls!$B$6)+5)*(COLUMN($C$1:$BJ$1)-COLUMN($C$1)<Controls!$B$7)*$C$34:$BJ$34) -> 0
A36: Scenario Multiplier | B36: x | C36: =IF(Controls!$B$12="Upside",Controls!$B$13,IF(Controls!$B$12="Downside",Controls!$B$14,1)) -> 1 | D36: =IF(Controls!$B$12="Upside",Controls!$B$13,IF(Controls!$B$12="Downside",Controls!$B$14,1)) -> 1 | E36: =IF(Controls!$B$12="Upside",Controls!$B$13,IF(Controls!$B$12="Downside",Controls!$B$14,1)) -> 1 | F36: =IF(Controls!$B$12="Upside",Controls!$B$13,IF(Controls!$B$12="Downside",Controls!$B$14,1)) -> 1 | G36: =IF(Controls!$B$12="Upside",Controls!$B$13,IF(Controls!$B$12="Downside",Controls!$B$14,1)) -> 1 | H36: =IF(Controls!$B$12="Upside",Controls!$B$13,IF(Controls!$B$12="Downside",Controls!$B$14,1)) -> 1 | I36: =IF(Controls!$B$12="Upside",Controls!$B$13,IF(Controls!$B$12="Downside",Controls!$B$14,1)) -> 1 | J36: =IF(Controls!$B$12="Upside",Controls!$B$13,IF(Controls!$B$12="Downside",Controls!$B$14,1)) -> 1 | ... BJ36: =IF(Controls!$B$12="Upside",Controls!$B$13,IF(Controls!$B$12="Downside",Controls!$B$14,1)) -> 1 | BK36: =IFERROR(SUMPRODUCT((YEAR(EDATE(Controls!$B$6,COLUMN($C$1:$BJ$1)-COLUMN($C$1)))=YEAR(Controls!$B$6)+0)*(COLUMN($C$1:$BJ$1)-COLUMN($C$1)<Controls!$B$7)*$C$36:$BJ$36)/SUMPRODUCT((YEAR(EDATE(Controls!$B$6,COLUMN($C$1:$BJ$1)-COLUMN($C$1)))=YEAR(Controls!$B$6)+0)*(COLUMN($C$1:$BJ$1)-COLUMN($C$1)<Controls!$B$7)*1),0) -> 1 | BL36: =IFERROR(SUMPRODUCT((YEAR(EDATE(Controls!$B$6,COLUMN($C$1:$BJ$1)-COLUMN($C$1)))=YEAR(Controls!$B$6)+1)*(COLUMN($C$1:$BJ$1)-COLUMN($C$1)<Controls!$B$7)*$C$36:$BJ$36)/SUMPRODUCT((YEAR(EDATE(Controls!$B$6,COLUMN($C$1:$BJ$1)-COLUMN($C$1)))=YEAR(Controls!$B$6)+1)*(COLUMN($C$1:$BJ$1)-COLUMN($C$1)<Controls!$B$7)*1),0) -> 1 | BM36: =IFERROR(SUMPRODUCT((YEAR(EDATE(Controls!$B$6,COLUMN($C$1:$BJ$1)-COLUMN($C$1)))=YEAR(Controls!$B$6)+2)*(COLUMN($C$1:$BJ$1)-COLUMN($C$1)<Controls!$B$7)*$C$36:$BJ$36)/SUMPRODUCT((YEAR(EDATE(Controls!$B$6,COLUMN($C$1:$BJ$1)-COLUMN($C$1)))=YEAR(Controls!$B$6)+2)*(COLUMN($C$1:$BJ$1)-COLUMN($C$1)<Controls!$B$7)*1),0) -> 1 | BN36: =IFERROR(SUMPRODUCT((YEAR(EDATE(Controls!$B$6,COLUMN($C$1:$BJ$1)-COLUMN($C$1)))=YEAR(Controls!$B$6)+3)*(COLUMN($C$1:$BJ$1)-COLUMN($C$1)<Controls!$B$7)*$C$36:$BJ$36)/SUMPRODUCT((YEAR(EDATE(Controls!$B$6,COLUMN($C$1:$BJ$1)-COLUMN($C$1)))=YEAR(Controls!$B$6)+3)*(COLUMN($C$1:$BJ$1)-COLUMN($C$1)<Controls!$B$7)*1),0) -> 0 | BO36: =IFERROR(SUMPRODUCT((YEAR(EDATE(Controls!$B$6,COLUMN($C$1:$BJ$1)-COLUMN($C$1)))=YEAR(Controls!$B$6)+4)*(COLUMN($C$1:$BJ$1)-COLUMN($C$1)<Controls!$B$7)*$C$36:$BJ$36)/SUMPRODUCT((YEAR(EDATE(Controls!$B$6,COLUMN($C$1:$BJ$1)-COLUMN($C$1)))=YEAR(Controls!$B$6)+4)*(COLUMN($C$1:$BJ$1)-COLUMN($C$1)<Controls!$B$7)*1),0) -> 0 | BP36: =IFERROR(SUMPRODUCT((YEAR(EDATE(Controls!$B$6,COLUMN($C$1:$BJ$1)-COLUMN($C$1)))=YEAR(Controls!$B$6)+5)*(COLUMN($C$1:$BJ$1)-COLUMN($C$1)<Controls!$B$7)*$C$36:$BJ$36)/SUMPRODUCT((YEAR(EDATE(Controls!$B$6,COLUMN($C$1:$BJ$1)-COLUMN($C$1)))=YEAR(Controls!$B$6)+5)*(COLUMN($C$1:$BJ$1)-COLUMN($C$1)<Controls!$B$7)*1),0) -> 0
A37: TOTAL NEW CUSTOMERS | B37: # | C37: =ROUND((C20+C27+C34)*C36,0) -> 62 | D37: =ROUND((D20+D27+D34)*D36,0) -> 65 | E37: =ROUND((E20+E27+E34)*E36,0) -> 69 | F37: =ROUND((F20+F27+F34)*F36,0) -> 74 | G37: =ROUND((G20+G27+G34)*G36,0) -> 79 | H37: =ROUND((H20+H27+H34)*H36,0) -> 84 | I37: =ROUND((I20+I27+I34)*I36,0) -> 88 | J37: =ROUND((J20+J27+J34)*J36,0) -> 94 | ... BJ37: =ROUND((BJ20+BJ27+BJ34)*BJ36,0) -> 0 | BK37: =SUMPRODUCT((YEAR(EDATE(Controls!$B$6,COLUMN($C$1:$BJ$1)-COLUMN($C$1)))=YEAR(Controls!$B$6)+0)*(COLUMN($C$1:$BJ$1)-COLUMN($C$1)<Controls!$B$7)*$C$37:$BJ$37) -> 1052 | BL37: =SUMPRODUCT((YEAR(EDATE(Controls!$B$6,COLUMN($C$1:$BJ$1)-COLUMN($C$1)))=YEAR(Controls!$B$6)+1)*(COLUMN($C$1:$BJ$1)-COLUMN($C$1)<Controls!$B$7)*$C$37:$BJ$37) -> 2196 | BM37: =SUMPRODUCT((YEAR(EDATE(Controls!$B$6,COLUMN($C$1:$BJ$1)-COLUMN($C$1)))=YEAR(Controls!$B$6)+2)*(COLUMN($C$1:$BJ$1)-COLUMN($C$1)<Controls!$B$7)*$C$37:$BJ$37) -> 4716 | BN37: =SUMPRODUCT((YEAR(EDATE(Controls!$B$6,COLUMN($C$1:$BJ$1)-COLUMN($C$1)))=YEAR(Controls!$B$6)+3)*(COLUMN($C$1:$BJ$1)-COLUMN($C$1)<Controls!$B$7)*$C$37:$BJ$37) -> 0 | BO37: =SUMPRODUCT((YEAR(EDATE(Controls!$B$6,COLUMN($C$1:$BJ$1)-COLUMN($C$1)))=YEAR(Controls!$B$6)+4)*(COLUMN($C$1:$BJ$1)-COLUMN($C$1)<Controls!$B$7)*$C$37:$BJ$37) -> 0 | BP37: =SUMPRODUCT((YEAR(EDATE(Controls!$B$6,COLUMN($C$1:$BJ$1)-COLUMN($C$1)))=YEAR(Controls!$B$6)+5)*(COLUMN($C$1:$BJ$1)-COLUMN($C$1)<Controls!$B$7)*$C$37:$BJ$37) -> 0
A39: CUSTOMER MIX BY TIER
A40: New Customer Mix – Starter | B40: % | C40: 0.6
A41: New Customer Mix – Growth | B41: % | C41: 0.3
A42: New Customer Mix – Enterprise | B42: % | C42: 0.1
A43: Mix Total (must = 100%) | B43: % | C43: =C40+C41+C42 -> 1
A45: CUSTOMER WATERFALL – STARTER
A46: Beginning Customers – Starter | B46: # | C46: =5 -> 5 | D46: =C49 -> 42 | E46: =D49 -> 80 | F46: =E49 -> 119 | G46: =F49 -> 159 | H46: =G49 -> 201 | I46: =H49 -> 245 | J46: =I49 -> 291 | K46: =J49 -> 338 | ... BJ46: =BI49 -> 1749
A47: + New Customers – Starter | B47: # | C47: =ROUND(C37*$C$40,0) -> 37 | D47: =ROUND(D37*$C$40,0) -> 39 | E47: =ROUND(E37*$C$40,0) -> 41 | F47: =ROUND(F37*$C$40,0) -> 44 | G47: =ROUND(G37*$C$40,0) -> 47 | H47: =ROUND(H37*$C$40,0) -> 50 | I47: =ROUND(I37*$C$40,0) -> 53 | J47: =ROUND(J37*$C$40,0) -> 56 | ... BJ47: =ROUND(BJ37*$C$40,0) -> 0 | BK47: =SUMPRODUCT((YEAR(EDATE(Controls!$B$6,COLUMN($C$1:$BJ$1)-COLUMN($C$1)))=YEAR(Controls!$B$6)+0)*(COLUMN($C$1:$BJ$1)-COLUMN($C$1)<Controls!$B$7)*$C$47:$BJ$47) -> 629 | BL47: =SUMPRODUCT((YEAR(EDATE(Controls!$B$6,COLUMN($C$1:$BJ$1)-COLUMN($C$1)))=YEAR(Controls!$B$6)+1)*(COLUMN($C$1:$BJ$1)-COLUMN($C$1)<Controls!$B$7)*$C$47:$BJ$47) -> 1317 | BM47: =SUMPRODUCT((YEAR(EDATE(Controls!$B$6,COLUMN($C$1:$BJ$1)-COLUMN($C$1)))=YEAR(Controls!$B$6)+2)*(COLUMN($C$1:$BJ$1)-COLUMN($C$1)<Controls!$B$7)*$C$47:$BJ$47) -> 2831 | BN47: =SUMPRODUCT((YEAR(EDATE(Controls!$B$6,COLUMN($C$1:$BJ$1)-COLUMN($C$1)))=YEAR(Controls!$B$6)+3)*(COLUMN($C$1:$BJ$1)-COLUMN($C$1)<Controls!$B$7)*$C$47:$BJ$47) -> 0 | BO47: =SUMPRODUCT((YEAR(EDATE(Controls!$B$6,COLUMN($C$1:$BJ$1)-COLUMN($C$1)))=YEAR(Controls!$B$6)+4)*(COLUMN($C$1:$BJ$1)-COLUMN($C$1)<Controls!$B$7)*$C$47:$BJ$47) -> 0 | BP47: =SUMPRODUCT((YEAR(EDATE(Controls!$B$6,COLUMN($C$1:$BJ$1)-COLUMN($C$1)))=YEAR(Controls!$B$6)+5)*(COLUMN($C$1:$BJ$1)-COLUMN($C$1)<Controls!$B$7)*$C$47:$BJ$47) -> 0
A48: – Churned Customers – Starter | B48: # | C48: =-ROUND(C46*$C$50*IF(Controls!$B$12="Upside",Controls!$B$15,IF(Controls!$B$12="Downside",Controls!$B$16,1)),0) -> 0 | D48: =-ROUND(D46*$C$50*IF(Controls!$B$12="Upside",Controls!$B$15,IF(Controls!$B$12="Downside",Controls!$B$16,1)),0) -> -1 | E48: =-ROUND(E46*$C$50*IF(Controls!$B$12="Upside",Controls!$B$15,IF(Controls!$B$12="Downside",Controls!$B$16,1)),0) -> -2 | F48: =-ROUND(F46*$C$50*IF(Controls!$B$12="Upside",Controls!$B$15,IF(Controls!$B$12="Downside",Controls!$B$16,1)),0) -> -4 | G48: =-ROUND(G46*$C$50*IF(Controls!$B$12="Upside",Controls!$B$15,IF(Controls!$B$12="Downside",Controls!$B$16,1)),0) -> -5 | H48: =-ROUND(H46*$C$50*IF(Controls!$B$12="Upside",Controls!$B$15,IF(Controls!$B$12="Downside",Controls!$B$16,1)),0) -> -6 | I48: =-ROUND(I46*$C$50*IF(Controls!$B$12="Upside",Controls!$B$15,IF(Controls!$B$12="Downside",Controls!$B$16,1)),0) -> -7 | J48: =-ROUND(J46*$C$50*IF(Controls!$B$12="Upside",Controls!$B$15,IF(Controls!$B$12="Downside",Controls!$B$16,1)),0) -> -9 | ... BJ48: =-ROUND(BJ46*$C$50*IF(Controls!$B$12="Upside",Controls!$B$15,IF(Controls!$B$12="Downside",Controls!$B$16,1)),0) -> -52 | BK48: =SUMPRODUCT((YEAR(EDATE(Controls!$B$6,COLUMN($C$1:$BJ$1)-COLUMN($C$1)))=YEAR(Controls!$B$6)+0)*(COLUMN($C$1:$BJ$1)-COLUMN($C$1)<Controls!$B$7)*$C$48:$BJ$48) -> -84 | BL48: =SUMPRODUCT((YEAR(EDATE(Controls!$B$6,COLUMN($C$1:$BJ$1)-COLUMN($C$1)))=YEAR(Controls!$B$6)+1)*(COLUMN($C$1:$BJ$1)-COLUMN($C$1)<Controls!$B$7)*$C$48:$BJ$48) -> -340 | BM48: =SUMPRODUCT((YEAR(EDATE(Controls!$B$6,COLUMN($C$1:$BJ$1)-COLUMN($C$1)))=YEAR(Controls!$B$6)+2)*(COLUMN($C$1:$BJ$1)-COLUMN($C$1)<Controls!$B$7)*$C$48:$BJ$48) -> -834 | BN48: =SUMPRODUCT((YEAR(EDATE(Controls!$B$6,COLUMN($C$1:$BJ$1)-COLUMN($C$1)))=YEAR(Controls!$B$6)+3)*(COLUMN($C$1:$BJ$1)-COLUMN($C$1)<Controls!$B$7)*$C$48:$BJ$48) -> 0 | BO48: =SUMPRODUCT((YEAR(EDATE(Controls!$B$6,COLUMN($C$1:$BJ$1)-COLUMN($C$1)))=YEAR(Controls!$B$6)+4)*(COLUMN($C$1:$BJ$1)-COLUMN($C$1)<Controls!$B$7)*$C$48:$BJ$48) -> 0 | BP48: =SUMPRODUCT((YEAR(EDATE(Controls!$B$6,COLUMN($C$1:$BJ$1)-COLUMN($C$1)))=YEAR(Controls!$B$6)+5)*(COLUMN($C$1:$BJ$1)-COLUMN($C$1)<Controls!$B$7)*$C$48:$BJ$48) -> 0
...

Sheet Charts
A1: SaaS Financial Plan · Key Metrics Dashboard · 36-Month Forecast

Sheet Headcount
A1: HEADCOUNT PLAN · Role-Level Wage Forecast · Includes Benefits & Payroll Taxes
A3: Label | B3: Unit | C3: =TEXT(EDATE(Controls!$B$6,0),"mmm-yy") -> Jan-26 | D3: =TEXT(EDATE(Controls!$B$6,1),"mmm-yy") -> Feb-26 | E3: =TEXT(EDATE(Controls!$B$6,2),"mmm-yy") -> Mar-26 | F3: =TEXT(EDATE(Controls!$B$6,3),"mmm-yy") -> Apr-26 | G3: =TEXT(EDATE(Controls!$B$6,4),"mmm-yy") -> May-26 | H3: =TEXT(EDATE(Controls!$B$6,5),"mmm-yy") -> Jun-26 | I3: =TEXT(EDATE(Controls!$B$6,6),"mmm-yy") -> Jul-26 | J3: =TEXT(EDATE(Controls!$B$6,7),"mmm-yy") -> Aug-26 | K3: =TEXT(EDATE(Controls!$B$6,8),"mmm-yy") -> Sep-26 | L3: =TEXT(EDATE(Controls!$B$6,9),"mmm-yy") -> Oct-26 | M3: =TEXT(EDATE(Controls!$B$6,10),"mmm-yy") -> Nov-26 | N3: =TEXT(EDATE(Controls!$B$6,11),"mmm-yy") -> Dec-26 | O3: =TEXT(EDATE(Controls!$B$6,12),"mmm-yy") -> Jan-27 | P3: =TEXT(EDATE(Controls!$B$6,13),"mmm-yy") -> Feb-27 | Q3: =TEXT(EDATE(Controls!$B$6,14),"mmm-yy") -> Mar-27 | R3: =TEXT(EDATE(Controls!$B$6,15),"mmm-yy") -> Apr-27 | S3: =TEXT(EDATE(Controls!$B$6,16),"mmm-yy") -> May-27 | T3: =TEXT(EDATE(Controls!$B$6,17),"mmm-yy") -> Jun-27 | U3: =TEXT(EDATE(Controls!$B$6,18),"mmm-yy") -> Jul-27 | V3: =TEXT(EDATE(Controls!$B$6,19),"mmm-yy") -> Aug-27 | W3: =TEXT(EDATE(Controls!$B$6,20),"mmm-yy") -> Sep-27 | X3: =TEXT(EDATE(Controls!$B$6,21),"mmm-yy") -> Oct-27 | Y3: =TEXT(EDATE(Controls!$B$6,22),"mmm-yy") -> Nov-27 | Z3: =TEXT(EDATE(Controls!$B$6,23),"mmm-yy") -> Dec-27 | AA3: =TEXT(EDATE(Controls!$B$6,24),"mmm-yy") -> Jan-28 | AB3: =TEXT(EDATE(Controls!$B$6,25),"mmm-yy") -> Feb-28 | AC3: =TEXT(EDATE(Controls!$B$6,26),"mmm-yy") -> Mar-28 | AD3: =TEXT(EDATE(Controls!$B$6,27),"mmm-yy") -> Apr-28 | AE3: =TEXT(EDATE(Controls!$B$6,28),"mmm-yy") -> May-28 | AF3: =TEXT(EDATE(Controls!$B$6,29),"mmm-yy") -> Jun-28 | AG3: =TEXT(EDATE(Controls!$B$6,30),"mmm-yy") -> Jul-28 | AH3: =TEXT(EDATE(Controls!$B$6,31),"mmm-yy") -> Aug-28 | AI3: =TEXT(EDATE(Controls!$B$6,32),"mmm-yy") -> Sep-28 | AJ3: =TEXT(EDATE(Controls!$B$6,33),"mmm-yy") -> Oct-28 | AK3: =TEXT(EDATE(Controls!$B$6,34),"mmm-yy") -> Nov-28 | AL3: =TEXT(EDATE(Controls!$B$6,35),"mmm-yy") -> Dec-28 | AM3: =TEXT(EDATE(Controls!$B$6,36),"mmm-yy") -> Jan-29 | AN3: =TEXT(EDATE(Controls!$B$6,37),"mmm-yy") -> Feb-29 | AO3: =TEXT(EDATE(Controls!$B$6,38),"mmm-yy") -> Mar-29 | AP3: =TEXT(EDATE(Controls!$B$6,39),"mmm-yy") -> Apr-29 | AQ3: =TEXT(EDATE(Controls!$B$6,40),"mmm-yy") -> May-29 | AR3: =TEXT(EDATE(Controls!$B$6,41),"mmm-yy") -> Jun-29 | AS3: =TEXT(EDATE(Controls!$B$6,42),"mmm-yy") -> Jul-29 | AT3: =TEXT(EDATE(Controls!$B$6,43),"mmm-yy") -> Aug-29 | AU3: =TEXT(EDATE(Controls!$B$6,44),"mmm-yy") -> Sep-29 | AV3: =TEXT(EDATE(Controls!$B$6,45),"mmm-yy") -> Oct-29 | AW3: =TEXT(EDATE(Controls!$B$6,46),"mmm-yy") -> Nov-29 | AX3: =TEXT(EDATE(Controls!$B$6,47),"mmm-yy") -> Dec-29 | AY3: =TEXT(EDATE(Controls!$B$6,48),"mmm-yy") -> Jan-30 | AZ3: =TEXT(EDATE(Controls!$B$6,49),"mmm-yy") -> Feb-30 | BA3: =TEXT(EDATE(Controls!$B$6,50),"mmm-yy") -> Mar-30 | BB3: =TEXT(EDATE(Controls!$B$6,51),"mmm-yy") -> Apr-30 | BC3: =TEXT(EDATE(Controls!$B$6,52),"mmm-yy") -> May-30 | BD3: =TEXT(EDATE(Controls!$B$6,53),"mmm-yy") -> Jun-30 | BE3: =TEXT(EDATE(Controls!$B$6,54),"mmm-yy") -> Jul-30 | BF3: =TEXT(EDATE(Controls!$B$6,55),"mmm-yy") -> Aug-30 | BG3: =TEXT(EDATE(Controls!$B$6,56),"mmm-yy") -> Sep-30 | BH3: =TEXT(EDATE(Controls!$B$6,57),"mmm-yy") -> Oct-30 | BI3: =TEXT(EDATE(Controls!$B$6,58),"mmm-yy") -> Nov-30 | BJ3: =TEXT(EDATE(Controls!$B$6,59),"mmm-yy") -> Dec-30 | BK3: ="FY "&(YEAR(Controls!$B$6)+0) -> FY 2026 | BL3: ="FY "&(YEAR(Controls!$B$6)+1) -> FY 2027 | BM3: ="FY "&(YEAR(Controls!$B$6)+2) -> FY 2028 | BN3: ="FY "&(YEAR(Controls!$B$6)+3) -> FY 2029 | BO3: ="FY "&(YEAR(Controls!$B$6)+4) -> FY 2030 | BP3: ="FY "&(YEAR(Controls!$B$6)+5) -> FY 2031
A5: HEADCOUNT WAGES BY DEPARTMENT (Benefits & Payroll Tax Built In)
A6: Year 1 (months 1–12): enter base salary cost directly. Years 2–3 auto-calculate from the rolling 12-month prior period × (1 + YoY growth rate). Growth kicks in exactly 12 months after model start — not on a calendar-year boundary.
A7: COGS – Customer Success
A8: YoY Headcount Cost Growth Rate – COGS – Customer Success | B8: %/yr | C8: 0.2 | D8: ↑ Applies to months 13–36 (rolling 12-mo, not calendar year)
A9: Base Salary Cost – COGS – Customer Success | B9: $/mo | C9: 8000 | D9: 8000 | E9: 8000 | F9: 8000 | G9: 8000 | H9: 8000 | I9: 8000 | J9: 8000 | K9: 8000 | L9: 8000 | M9: 8000 | N9: 8000 | O9: =IF(COLUMN()-2<=Controls!$B$7,C9*(1+$C$8),0) -> 9600 | P9: =IF(COLUMN()-2<=Controls!$B$7,D9*(1+$C$8),0) -> 9600 | Q9: =IF(COLUMN()-2<=Controls!$B$7,E9*(1+$C$8),0) -> 9600 | R9: =IF(COLUMN()-2<=Controls!$B$7,F9*(1+$C$8),0) -> 9600 | S9: =IF(COLUMN()-2<=Controls!$B$7,G9*(1+$C$8),0) -> 9600 | T9: =IF(COLUMN()-2<=Controls!$B$7,H9*(1+$C$8),0) -> 9600 | U9: =IF(COLUMN()-2<=Controls!$B$7,I9*(1+$C$8),0) -> 9600 | V9: =IF(COLUMN()-2<=Controls!$B$7,J9*(1+$C$8),0) -> 9600 | ... BJ9: =IF(COLUMN()-2<=Controls!$B$7,AX9*(1+$C$8),0) -> 0 | BK9: =SUMPRODUCT((YEAR(EDATE(Controls!$B$6,COLUMN($C$1:$BJ$1)-COLUMN($C$1)))=YEAR(Controls!$B$6)+0)*(COLUMN($C$1:$BJ$1)-COLUMN($C$1)<Controls!$B$7)*$C$9:$BJ$9) -> 96000 | BL9: =SUMPRODUCT((YEAR(EDATE(Controls!$B$6,COLUMN($C$1:$BJ$1)-COLUMN($C$1)))=YEAR(Controls!$B$6)+1)*(COLUMN($C$1:$BJ$1)-COLUMN($C$1)<Controls!$B$7)*$C$9:$BJ$9) -> 115200 | BM9: =SUMPRODUCT((YEAR(EDATE(Controls!$B$6,COLUMN($C$1:$BJ$1)-COLUMN($C$1)))=YEAR(Controls!$B$6)+2)*(COLUMN($C$1:$BJ$1)-COLUMN($C$1)<Controls!$B$7)*$C$9:$BJ$9) -> 138240 | BN9: =SUMPRODUCT((YEAR(EDATE(Controls!$B$6,COLUMN($C$1:$BJ$1)-COLUMN($C$1)))=YEAR(Controls!$B$6)+3)*(COLUMN($C$1:$BJ$1)-COLUMN($C$1)<Controls!$B$7)*$C$9:$BJ$9) -> 0 | BO9: =SUMPRODUCT((YEAR(EDATE(Controls!$B$6,COLUMN($C$1:$BJ$1)-COLUMN($C$1)))=YEAR(Controls!$B$6)+4)*(COLUMN($C$1:$BJ$1)-COLUMN($C$1)<Controls!$B$7)*$C$9:$BJ$9) -> 0 | BP9: =SUMPRODUCT((YEAR(EDATE(Controls!$B$6,COLUMN($C$1:$BJ$1)-COLUMN($C$1)))=YEAR(Controls!$B$6)+5)*(COLUMN($C$1:$BJ$1)-COLUMN($C$1)<Controls!$B$7)*$C$9:$BJ$9) -> 0
A10: Total Loaded Cost – COGS – Customer Success (incl. benefits & taxes) | B10: $/mo | C10: =C9*(1+Controls!$B$25+Controls!$B$24) -> 10052 | D10: =D9*(1+Controls!$B$25+Controls!$B$24) -> 10052 | E10: =E9*(1+Controls!$B$25+Controls!$B$24) -> 10052 | F10: =F9*(1+Controls!$B$25+Controls!$B$24) -> 10052 | G10: =G9*(1+Controls!$B$25+Controls!$B$24) -> 10052 | H10: =H9*(1+Controls!$B$25+Controls!$B$24) -> 10052 | I10: =I9*(1+Controls!$B$25+Controls!$B$24) -> 10052 | J10: =J9*(1+Controls!$B$25+Controls!$B$24) -> 10052 | ... BJ10: =BJ9*(1+Controls!$B$25+Controls!$B$24) -> 0 | BK10: =SUMPRODUCT((YEAR(EDATE(Controls!$B$6,COLUMN($C$1:$BJ$1)-COLUMN($C$1)))=YEAR(Controls!$B$6)+0)*(COLUMN($C$1:$BJ$1)-COLUMN($C$1)<Controls!$B$7)*$C$10:$BJ$10) -> 120624 | BL10: =SUMPRODUCT((YEAR(EDATE(Controls!$B$6,COLUMN($C$1:$BJ$1)-COLUMN($C$1)))=YEAR(Controls!$B$6)+1)*(COLUMN($C$1:$BJ$1)-COLUMN($C$1)<Controls!$B$7)*$C$10:$BJ$10) -> 144748.8 | BM10: =SUMPRODUCT((YEAR(EDATE(Controls!$B$6,COLUMN($C$1:$BJ$1)-COLUMN($C$1)))=YEAR(Controls!$B$6)+2)*(COLUMN($C$1:$BJ$1)-COLUMN($C$1)<Controls!$B$7)*$C$10:$BJ$10) -> 173698.56 | BN10: =SUMPRODUCT((YEAR(EDATE(Controls!$B$6,COLUMN($C$1:$BJ$1)-COLUMN($C$1)))=YEAR(Controls!$B$6)+3)*(COLUMN($C$1:$BJ$1)-COLUMN($C$1)<Controls!$B$7)*$C$10:$BJ$10) -> 0 | BO10: =SUMPRODUCT((YEAR(EDATE(Controls!$B$6,COLUMN($C$1:$BJ$1)-COLUMN($C$1)))=YEAR(Controls!$B$6)+4)*(COLUMN($C$1:$BJ$1)-COLUMN($C$1)<Controls!$B$7)*$C$10:$BJ$10) -> 0 | BP10: =SUMPRODUCT((YEAR(EDATE(Controls!$B$6,COLUMN($C$1:$BJ$1)-COLUMN($C$1)))=YEAR(Controls!$B$6)+5)*(COLUMN($C$1:$BJ$1)-COLUMN($C$1)<Controls!$B$7)*$C$10:$BJ$10) -> 0
A12: Sales & Marketing
A13: YoY Headcount Cost Growth Rate – Sales & Marketing | B13: %/yr | C13: 0.3 | D13: ↑ Applies to months 13–36 (rolling 12-mo, not calendar year)
A14: Base Salary Cost – Sales & Marketing | B14: $/mo | C14: 15000 | D14: 15000 | E14: 15000 | F14: 15000 | G14: 15000 | H14: 15000 | I14: 15000 | J14: 15000 | K14: 15000 | L14: 15000 | M14: 15000 | N14: 15000 | O14: =IF(COLUMN()-2<=Controls!$B$7,C14*(1+$C$13),0) -> 19500 | P14: =IF(COLUMN()-2<=Controls!$B$7,D14*(1+$C$13),0) -> 19500 | Q14: =IF(COLUMN()-2<=Controls!$B$7,E14*(1+$C$13),0) -> 19500 | R14: =IF(COLUMN()-2<=Controls!$B$7,F14*(1+$C$13),0) -> 19500 | S14: =IF(COLUMN()-2<=Controls!$B$7,G14*(1+$C$13),0) -> 19500 | T14: =IF(COLUMN()-2<=Controls!$B$7,H14*(1+$C$13),0) -> 19500 | U14: =IF(COLUMN()-2<=Controls!$B$7,I14*(1+$C$13),0) -> 19500 | V14: =IF(COLUMN()-2<=Controls!$B$7,J14*(1+$C$13),0) -> 19500 | ... BJ14: =IF(COLUMN()-2<=Controls!$B$7,AX14*(1+$C$13),0) -> 0 | BK14: =SUMPRODUCT((YEAR(EDATE(Controls!$B$6,COLUMN($C$1:$BJ$1)-COLUMN($C$1)))=YEAR(Controls!$B$6)+0)*(COLUMN($C$1:$BJ$1)-COLUMN($C$1)<Controls!$B$7)*$C$14:$BJ$14) -> 180000 | BL14: =SUMPRODUCT((YEAR(EDATE(Controls!$B$6,COLUMN($C$1:$BJ$1)-COLUMN($C$1)))=YEAR(Controls!$B$6)+1)*(COLUMN($C$1:$BJ$1)-COLUMN($C$1)<Controls!$B$7)*$C$14:$BJ$14) -> 234000 | BM14: =SUMPRODUCT((YEAR(EDATE(Controls!$B$6,COLUMN($C$1:$BJ$1)-COLUMN($C$1)))=YEAR(Controls!$B$6)+2)*(COLUMN($C$1:$BJ$1)-COLUMN($C$1)<Controls!$B$7)*$C$14:$BJ$14) -> 304200 | BN14: =SUMPRODUCT((YEAR(EDATE(Controls!$B$6,COLUMN($C$1:$BJ$1)-COLUMN($C$1)))=YEAR(Controls!$B$6)+3)*(COLUMN($C$1:$BJ$1)-COLUMN($C$1)<Controls!$B$7)*$C$14:$BJ$14) -> 0 | BO14: =SUMPRODUCT((YEAR(EDATE(Controls!$B$6,COLUMN($C$1:$BJ$1)-COLUMN($C$1)))=YEAR(Controls!$B$6)+4)*(COLUMN($C$1:$BJ$1)-COLUMN($C$1)<Controls!$B$7)*$C$14:$BJ$14) -> 0 | BP14: =SUMPRODUCT((YEAR(EDATE(Controls!$B$6,COLUMN($C$1:$BJ$1)-COLUMN($C$1)))=YEAR(Controls!$B$6)+5)*(COLUMN($C$1:$BJ$1)-COLUMN($C$1)<Controls!$B$7)*$C$14:$BJ$14) -> 0
A15: Total Loaded Cost – Sales & Marketing (incl. benefits & taxes) | B15: $/mo | C15: =C14*(1+Controls!$B$25+Controls!$B$24) -> 18847.5 | D15: =D14*(1+Controls!$B$25+Controls!$B$24) -> 18847.5 | E15: =E14*(1+Controls!$B$25+Controls!$B$24) -> 18847.5 | F15: =F14*(1+Controls!$B$25+Controls!$B$24) -> 18847.5 | G15: =G14*(1+Controls!$B$25+Controls!$B$24) -> 18847.5 | H15: =H14*(1+Controls!$B$25+Controls!$B$24) -> 18847.5 | I15: =I14*(1+Controls!$B$25+Controls!$B$24) -> 18847.5 | J15: =J14*(1+Controls!$B$25+Controls!$B$24) -> 18847.5 | ... BJ15: =BJ14*(1+Controls!$B$25+Controls!$B$24) -> 0 | BK15: =SUMPRODUCT((YEAR(EDATE(Controls!$B$6,COLUMN($C$1:$BJ$1)-COLUMN($C$1)))=YEAR(Controls!$B$6)+0)*(COLUMN($C$1:$BJ$1)-COLUMN($C$1)<Controls!$B$7)*$C$15:$BJ$15) -> 226170 | BL15: =SUMPRODUCT((YEAR(EDATE(Controls!$B$6,COLUMN($C$1:$BJ$1)-COLUMN($C$1)))=YEAR(Controls!$B$6)+1)*(COLUMN($C$1:$BJ$1)-COLUMN($C$1)<Controls!$B$7)*$C$15:$BJ$15) -> 294021 | BM15: =SUMPRODUCT((YEAR(EDATE(Controls!$B$6,COLUMN($C$1:$BJ$1)-COLUMN($C$1)))=YEAR(Controls!$B$6)+2)*(COLUMN($C$1:$BJ$1)-COLUMN($C$1)<Controls!$B$7)*$C$15:$BJ$15) -> 382227.3 | BN15: =SUMPRODUCT((YEAR(EDATE(Controls!$B$6,COLUMN($C$1:$BJ$1)-COLUMN($C$1)))=YEAR(Controls!$B$6)+3)*(COLUMN($C$1:$BJ$1)-COLUMN($C$1)<Controls!$B$7)*$C$15:$BJ$15) -> 0 | BO15: =SUMPRODUCT((YEAR(EDATE(Controls!$B$6,COLUMN($C$1:$BJ$1)-COLUMN($C$1)))=YEAR(Controls!$B$6)+4)*(COLUMN($C$1:$BJ$1)-COLUMN($C$1)<Controls!$B$7)*$C$15:$BJ$15) -> 0 | BP15: =SUMPRODUCT((YEAR(EDATE(Controls!$B$6,COLUMN($C$1:$BJ$1)-COLUMN($C$1)))=YEAR(Controls!$B$6)+5)*(COLUMN($C$1:$BJ$1)-COLUMN($C$1)<Controls!$B$7)*$C$15:$BJ$15) -> 0
A17: R&D / Engineering
A18: YoY Headcount Cost Growth Rate – R&D / Engineering | B18: %/yr | C18: 0.25 | D18: ↑ Applies to months 13–36 (rolling 12-mo, not calendar year)
A19: Base Salary Cost – R&D / Engineering | B19: $/mo | C19: 20000 | D19: 20000 | E19: 20000 | F19: 20000 | G19: 20000 | H19: 20000 | I19: 20000 | J19: 20000 | K19: 20000 | L19: 20000 | M19: 20000 | N19: 20000 | O19: =IF(COLUMN()-2<=Controls!$B$7,C19*(1+$C$18),0) -> 25000 | P19: =IF(COLUMN()-2<=Controls!$B$7,D19*(1+$C$18),0) -> 25000 | Q19: =IF(COLUMN()-2<=Controls!$B$7,E19*(1+$C$18),0) -> 25000 | R19: =IF(COLUMN()-2<=Controls!$B$7,F19*(1+$C$18),0) -> 25000 | S19: =IF(COLUMN()-2<=Controls!$B$7,G19*(1+$C$18),0) -> 25000 | T19: =IF(COLUMN()-2<=Controls!$B$7,H19*(1+$C$18),0) -> 25000 | U19: =IF(COLUMN()-2<=Controls!$B$7,I19*(1+$C$18),0) -> 25000 | V19: =IF(COLUMN()-2<=Controls!$B$7,J19*(1+$C$18),0) -> 25000 | ... BJ19: =IF(COLUMN()-2<=Controls!$B$7,AX19*(1+$C$18),0) -> 0 | BK19: =SUMPRODUCT((YEAR(EDATE(Controls!$B$6,COLUMN($C$1:$BJ$1)-COLUMN($C$1)))=YEAR(Controls!$B$6)+0)*(COLUMN($C$1:$BJ$1)-COLUMN($C$1)<Controls!$B$7)*$C$19:$BJ$19) -> 240000 | BL19: =SUMPRODUCT((YEAR(EDATE(Controls!$B$6,COLUMN($C$1:$BJ$1)-COLUMN($C$1)))=YEAR(Controls!$B$6)+1)*(COLUMN($C$1:$BJ$1)-COLUMN($C$1)<Controls!$B$7)*$C$19:$BJ$19) -> 300000 | BM19: =SUMPRODUCT((YEAR(EDATE(Controls!$B$6,COLUMN($C$1:$BJ$1)-COLUMN($C$1)))=YEAR(Controls!$B$6)+2)*(COLUMN($C$1:$BJ$1)-COLUMN($C$1)<Controls!$B$7)*$C$19:$BJ$19) -> 375000 | BN19: =SUMPRODUCT((YEAR(EDATE(Controls!$B$6,COLUMN($C$1:$BJ$1)-COLUMN($C$1)))=YEAR(Controls!$B$6)+3)*(COLUMN($C$1:$BJ$1)-COLUMN($C$1)<Controls!$B$7)*$C$19:$BJ$19) -> 0 | BO19: =SUMPRODUCT((YEAR(EDATE(Controls!$B$6,COLUMN($C$1:$BJ$1)-COLUMN($C$1)))=YEAR(Controls!$B$6)+4)*(COLUMN($C$1:$BJ$1)-COLUMN($C$1)<Controls!$B$7)*$C$19:$BJ$19) -> 0 | BP19: =SUMPRODUCT((YEAR(EDATE(Controls!$B$6,COLUMN($C$1:$BJ$1)-COLUMN($C$1)))=YEAR(Controls!$B$6)+5)*(COLUMN($C$1:$BJ$1)-COLUMN($C$1)<Controls!$B$7)*$C$19:$BJ$19) -> 0
A20: Total Loaded Cost – R&D / Engineering (incl. benefits & taxes) | B20: $/mo | C20: =C19*(1+Controls!$B$25+Controls!$B$24) -> 25130 | D20: =D19*(1+Controls!$B$25+Controls!$B$24) -> 25130 | E20: =E19*(1+Controls!$B$25+Controls!$B$24) -> 25130 | F20: =F19*(1+Controls!$B$25+Controls!$B$24) -> 25130 | G20: =G19*(1+Controls!$B$25+Controls!$B$24) -> 25130 | H20: =H19*(1+Controls!$B$25+Controls!$B$24) -> 25130 | I20: =I19*(1+Controls!$B$25+Controls!$B$24) -> 25130 | J20: =J19*(1+Controls!$B$25+Controls!$B$24) -> 25130 | ... BJ20: =BJ19*(1+Controls!$B$25+Controls!$B$24) -> 0 | BK20: =SUMPRODUCT((YEAR(EDATE(Controls!$B$6,COLUMN($C$1:$BJ$1)-COLUMN($C$1)))=YEAR(Controls!$B$6)+0)*(COLUMN($C$1:$BJ$1)-COLUMN($C$1)<Controls!$B$7)*$C$20:$BJ$20) -> 301560 | BL20: =SUMPRODUCT((YEAR(EDATE(Controls!$B$6,COLUMN($C$1:$BJ$1)-COLUMN($C$1)))=YEAR(Controls!$B$6)+1)*(COLUMN($C$1:$BJ$1)-COLUMN($C$1)<Controls!$B$7)*$C$20:$BJ$20) -> 376950 | BM20: =SUMPRODUCT((YEAR(EDATE(Controls!$B$6,COLUMN($C$1:$BJ$1)-COLUMN($C$1)))=YEAR(Controls!$B$6)+2)*(COLUMN($C$1:$BJ$1)-COLUMN($C$1)<Controls!$B$7)*$C$20:$BJ$20) -> 471187.5 | BN20: =SUMPRODUCT((YEAR(EDATE(Controls!$B$6,COLUMN($C$1:$BJ$1)-COLUMN($C$1)))=YEAR(Controls!$B$6)+3)*(COLUMN($C$1:$BJ$1)-COLUMN($C$1)<Controls!$B$7)*$C$20:$BJ$20) -> 0 | BO20: =SUMPRODUCT((YEAR(EDATE(Controls!$B$6,COLUMN($C$1:$BJ$1)-COLUMN($C$1)))=YEAR(Controls!$B$6)+4)*(COLUMN($C$1:$BJ$1)-COLUMN($C$1)<Controls!$B$7)*$C$20:$BJ$20) -> 0 | BP20: =SUMPRODUCT((YEAR(EDATE(Controls!$B$6,COLUMN($C$1:$BJ$1)-COLUMN($C$1)))=YEAR(Controls!$B$6)+5)*(COLUMN($C$1:$BJ$1)-COLUMN($C$1)<Controls!$B$7)*$C$20:$BJ$20) -> 0
A22: G&A
A23: YoY Headcount Cost Growth Rate – G&A | B23: %/yr | C23: 0.15 | D23: ↑ Applies to months 13–36 (rolling 12-mo, not calendar year)
A24: Base Salary Cost – G&A | B24: $/mo | C24: 10000 | D24: 10000 | E24: 10000 | F24: 10000 | G24: 10000 | H24: 10000 | I24: 10000 | J24: 10000 | K24: 10000 | L24: 10000 | M24: 10000 | N24: 10000 | O24: =IF(COLUMN()-2<=Controls!$B$7,C24*(1+$C$23),0) -> 11500 | P24: =IF(COLUMN()-2<=Controls!$B$7,D24*(1+$C$23),0) -> 11500 | Q24: =IF(COLUMN()-2<=Controls!$B$7,E24*(1+$C$23),0) -> 11500 | R24: =IF(COLUMN()-2<=Controls!$B$7,F24*(1+$C$23),0) -> 11500 | S24: =IF(COLUMN()-2<=Controls!$B$7,G24*(1+$C$23),0) -> 11500 | T24: =IF(COLUMN()-2<=Controls!$B$7,H24*(1+$C$23),0) -> 11500 | U24: =IF(COLUMN()-2<=Controls!$B$7,I24*(1+$C$23),0) -> 11500 | V24: =IF(COLUMN()-2<=Controls!$B$7,J24*(1+$C$23),0) -> 11500 | ... BJ24: =IF(COLUMN()-2<=Controls!$B$7,AX24*(1+$C$23),0) -> 0 | BK24: =SUMPRODUCT((YEAR(EDATE(Controls!$B$6,COLUMN($C$1:$BJ$1)-COLUMN($C$1)))=YEAR(Controls!$B$6)+0)*(COLUMN($C$1:$BJ$1)-COLUMN($C$1)<Controls!$B$7)*$C$24:$BJ$24) -> 120000 | BL24: =SUMPRODUCT((YEAR(EDATE(Controls!$B$6,COLUMN($C$1:$BJ$1)-COLUMN($C$1)))=YEAR(Controls!$B$6)+1)*(COLUMN($C$1:$BJ$1)-COLUMN($C$1)<Controls!$B$7)*$C$24:$BJ$24) -> 138000 | BM24: =SUMPRODUCT((YEAR(EDATE(Controls!$B$6,COLUMN($C$1:$BJ$1)-COLUMN($C$1)))=YEAR(Controls!$B$6)+2)*(COLUMN($C$1:$BJ$1)-COLUMN($C$1)<Controls!$B$7)*$C$24:$BJ$24) -> 158700 | BN24: =SUMPRODUCT((YEAR(EDATE(Controls!$B$6,COLUMN($C$1:$BJ$1)-COLUMN($C$1)))=YEAR(Controls!$B$6)+3)*(COLUMN($C$1:$BJ$1)-COLUMN($C$1)<Controls!$B$7)*$C$24:$BJ$24) -> 0 | BO24: =SUMPRODUCT((YEAR(EDATE(Controls!$B$6,COLUMN($C$1:$BJ$1)-COLUMN($C$1)))=YEAR(Controls!$B$6)+4)*(COLUMN($C$1:$BJ$1)-COLUMN($C$1)<Controls!$B$7)*$C$24:$BJ$24) -> 0 | BP24: =SUMPRODUCT((YEAR(EDATE(Controls!$B$6,COLUMN($C$1:$BJ$1)-COLUMN($C$1)))=YEAR(Controls!$B$6)+5)*(COLUMN($C$1:$BJ$1)-COLUMN($C$1)<Controls!$B$7)*$C$24:$BJ$24) -> 0
A25: Total Loaded Cost – G&A (incl. benefits & taxes) | B25: $/mo | C25: =C24*(1+Controls!$B$25+Controls!$B$24) -> 12565 | D25: =D24*(1+Controls!$B$25+Controls!$B$24) -> 12565 | E25: =E24*(1+Controls!$B$25+Controls!$B$24) -> 12565 | F25: =F24*(1+Controls!$B$25+Controls!$B$24) -> 12565 | G25: =G24*(1+Controls!$B$25+Controls!$B$24) -> 12565 | H25: =H24*(1+Controls!$B$25+Controls!$B$24) -> 12565 | I25: =I24*(1+Controls!$B$25+Controls!$B$24) -> 12565 | J25: =J24*(1+Controls!$B$25+Controls!$B$24) -> 12565 | ... BJ25: =BJ24*(1+Controls!$B$25+Controls!$B$24) -> 0 | BK25: =SUMPRODUCT((YEAR(EDATE(Controls!$B$6,COLUMN($C$1:$BJ$1)-COLUMN($C$1)))=YEAR(Controls!$B$6)+0)*(COLUMN($C$1:$BJ$1)-COLUMN($C$1)<Controls!$B$7)*$C$25:$BJ$25) -> 150780 | BL25: =SUMPRODUCT((YEAR(EDATE(Controls!$B$6,COLUMN($C$1:$BJ$1)-COLUMN($C$1)))=YEAR(Controls!$B$6)+1)*(COLUMN($C$1:$BJ$1)-COLUMN($C$1)<Controls!$B$7)*$C$25:$BJ$25) -> 173397 | BM25: =SUMPRODUCT((YEAR(EDATE(Controls!$B$6,COLUMN($C$1:$BJ$1)-COLUMN($C$1)))=YEAR(Controls!$B$6)+2)*(COLUMN($C$1:$BJ$1)-COLUMN($C$1)<Controls!$B$7)*$C$25:$BJ$25) -> 199406.55 | BN25: =SUMPRODUCT((YEAR(EDATE(Controls!$B$6,COLUMN($C$1:$BJ$1)-COLUMN($C$1)))=YEAR(Controls!$B$6)+3)*(COLUMN($C$1:$BJ$1)-COLUMN($C$1)<Controls!$B$7)*$C$25:$BJ$25) -> 0 | BO25: =SUMPRODUCT((YEAR(EDATE(Controls!$B$6,COLUMN($C$1:$BJ$1)-COLUMN($C$1)))=YEAR(Controls!$B$6)+4)*(COLUMN($C$1:$BJ$1)-COLUMN($C$1)<Controls!$B$7)*$C$25:$BJ$25) -> 0 | BP25: =SUMPRODUCT((YEAR(EDATE(Controls!$B$6,COLUMN($C$1:$BJ$1)-COLUMN($C$1)))=YEAR(Controls!$B$6)+5)*(COLUMN($C$1:$BJ$1)-COLUMN($C$1)<Controls!$B$7)*$C$25:$BJ$25) -> 0
A27: TOTAL LOADED WAGES (All Departments) | B27: $/mo | C27: =C10+C15+C20+C25 -> 66594.5 | D27: =D10+D15+D20+D25 -> 66594.5 | E27: =E10+E15+E20+E25 -> 66594.5 | F27: =F10+F15+F20+F25 -> 66594.5 | G27: =G10+G15+G20+G25 -> 66594.5 | H27: =H10+H15+H20+H25 -> 66594.5 | I27: =I10+I15+I20+I25 -> 66594.5 | J27: =J10+J15+J20+J25 -> 66594.5 | ... BJ27: =BJ10+BJ15+BJ20+BJ25 -> 0 | BK27: =SUMPRODUCT((YEAR(EDATE(Controls!$B$6,COLUMN($C$1:$BJ$1)-COLUMN($C$1)))=YEAR(Controls!$B$6)+0)*(COLUMN($C$1:$BJ$1)-COLUMN($C$1)<Controls!$B$7)*$C$27:$BJ$27) -> 799134 | BL27: =SUMPRODUCT((YEAR(EDATE(Controls!$B$6,COLUMN($C$1:$BJ$1)-COLUMN($C$1)))=YEAR(Controls!$B$6)+1)*(COLUMN($C$1:$BJ$1)-COLUMN($C$1)<Controls!$B$7)*$C$27:$BJ$27) -> 989116.8 | BM27: =SUMPRODUCT((YEAR(EDATE(Controls!$B$6,COLUMN($C$1:$BJ$1)-COLUMN($C$1)))=YEAR(Controls!$B$6)+2)*(COLUMN($C$1:$BJ$1)-COLUMN($C$1)<Controls!$B$7)*$C$27:$BJ$27) -> 1226519.9 | BN27: =SUMPRODUCT((YEAR(EDATE(Controls!$B$6,COLUMN($C$1:$BJ$1)-COLUMN($C$1)))=YEAR(Controls!$B$6)+3)*(COLUMN($C$1:$BJ$1)-COLUMN($C$1)<Controls!$B$7)*$C$27:$BJ$27) -> 0 | BO27: =SUMPRODUCT((YEAR(EDATE(Controls!$B$6,COLUMN($C$1:$BJ$1)-COLUMN($C$1)))=YEAR(Controls!$B$6)+4)*(COLUMN($C$1:$BJ$1)-COLUMN($C$1)<Controls!$B$7)*$C$27:$BJ$27) -> 0 | BP27: =SUMPRODUCT((YEAR(EDATE(Controls!$B$6,COLUMN($C$1:$BJ$1)-COLUMN($C$1)))=YEAR(Controls!$B$6)+5)*(COLUMN($C$1:$BJ$1)-COLUMN($C$1)<Controls!$B$7)*$C$27:$BJ$27) -> 0

Sheet OpEx
A1: NON-WAGE OPERATING EXPENSES · By Department
A3: Label | B3: Unit | C3: =TEXT(EDATE(Controls!$B$6,0),"mmm-yy") -> Jan-26 | D3: =TEXT(EDATE(Controls!$B$6,1),"mmm-yy") -> Feb-26 | E3: =TEXT(EDATE(Controls!$B$6,2),"mmm-yy") -> Mar-26 | F3: =TEXT(EDATE(Controls!$B$6,3),"mmm-yy") -> Apr-26 | G3: =TEXT(EDATE(Controls!$B$6,4),"mmm-yy") -> May-26 | H3: =TEXT(EDATE(Controls!$B$6,5),"mmm-yy") -> Jun-26 | I3: =TEXT(EDATE(Controls!$B$6,6),"mmm-yy") -> Jul-26 | J3: =TEXT(EDATE(Controls!$B$6,7),"mmm-yy") -> Aug-26 | K3: =TEXT(EDATE(Controls!$B$6,8),"mmm-yy") -> Sep-26 | L3: =TEXT(EDATE(Controls!$B$6,9),"mmm-yy") -> Oct-26 | M3: =TEXT(EDATE(Controls!$B$6,10),"mmm-yy") -> Nov-26 | N3: =TEXT(EDATE(Controls!$B$6,11),"mmm-yy") -> Dec-26 | O3: =TEXT(EDATE(Controls!$B$6,12),"mmm-yy") -> Jan-27 | P3: =TEXT(EDATE(Controls!$B$6,13),"mmm-yy") -> Feb-27 | Q3: =TEXT(EDATE(Controls!$B$6,14),"mmm-yy") -> Mar-27 | R3: =TEXT(EDATE(Controls!$B$6,15),"mmm-yy") -> Apr-27 | S3: =TEXT(EDATE(Controls!$B$6,16),"mmm-yy") -> May-27 | T3: =TEXT(EDATE(Controls!$B$6,17),"mmm-yy") -> Jun-27 | U3: =TEXT(EDATE(Controls!$B$6,18),"mmm-yy") -> Jul-27 | V3: =TEXT(EDATE(Controls!$B$6,19),"mmm-yy") -> Aug-27 | W3: =TEXT(EDATE(Controls!$B$6,20),"mmm-yy") -> Sep-27 | X3: =TEXT(EDATE(Controls!$B$6,21),"mmm-yy") -> Oct-27 | Y3: =TEXT(EDATE(Controls!$B$6,22),"mmm-yy") -> Nov-27 | Z3: =TEXT(EDATE(Controls!$B$6,23),"mmm-yy") -> Dec-27 | AA3: =TEXT(EDATE(Controls!$B$6,24),"mmm-yy") -> Jan-28 | AB3: =TEXT(EDATE(Controls!$B$6,25),"mmm-yy") -> Feb-28 | AC3: =TEXT(EDATE(Controls!$B$6,26),"mmm-yy") -> Mar-28 | AD3: =TEXT(EDATE(Controls!$B$6,27),"mmm-yy") -> Apr-28 | AE3: =TEXT(EDATE(Controls!$B$6,28),"mmm-yy") -> May-28 | AF3: =TEXT(EDATE(Controls!$B$6,29),"mmm-yy") -> Jun-28 | AG3: =TEXT(EDATE(Controls!$B$6,30),"mmm-yy") -> Jul-28 | AH3: =TEXT(EDATE(Controls!$B$6,31),"mmm-yy") -> Aug-28 | AI3: =TEXT(EDATE(Controls!$B$6,32),"mmm-yy") -> Sep-28 | AJ3: =TEXT(EDATE(Controls!$B$6,33),"mmm-yy") -> Oct-28 | AK3: =TEXT(EDATE(Controls!$B$6,34),"mmm-yy") -> Nov-28 | AL3: =TEXT(EDATE(Controls!$B$6,35),"mmm-yy") -> Dec-28 | AM3: =TEXT(EDATE(Controls!$B$6,36),"mmm-yy") -> Jan-29 | AN3: =TEXT(EDATE(Controls!$B$6,37),"mmm-yy") -> Feb-29 | AO3: =TEXT(EDATE(Controls!$B$6,38),"mmm-yy") -> Mar-29 | AP3: =TEXT(EDATE(Controls!$B$6,39),"mmm-yy") -> Apr-29 | AQ3: =TEXT(EDATE(Controls!$B$6,40),"mmm-yy") -> May-29 | AR3: =TEXT(EDATE(Controls!$B$6,41),"mmm-yy") -> Jun-29 | AS3: =TEXT(EDATE(Controls!$B$6,42),"mmm-yy") -> Jul-29 | AT3: =TEXT(EDATE(Controls!$B$6,43),"mmm-yy") -> Aug-29 | AU3: =TEXT(EDATE(Controls!$B$6,44),"mmm-yy") -> Sep-29 | AV3: =TEXT(EDATE(Controls!$B$6,45),"mmm-yy") -> Oct-29 | AW3: =TEXT(EDATE(Controls!$B$6,46),"mmm-yy") -> Nov-29 | AX3: =TEXT(EDATE(Controls!$B$6,47),"mmm-yy") -> Dec-29 | AY3: =TEXT(EDATE(Controls!$B$6,48),"mmm-yy") -> Jan-30 | AZ3: =TEXT(EDATE(Controls!$B$6,49),"mmm-yy") -> Feb-30 | BA3: =TEXT(EDATE(Controls!$B$6,50),"mmm-yy") -> Mar-30 | BB3: =TEXT(EDATE(Controls!$B$6,51),"mmm-yy") -> Apr-30 | BC3: =TEXT(EDATE(Controls!$B$6,52),"mmm-yy") -> May-30 | BD3: =TEXT(EDATE(Controls!$B$6,53),"mmm-yy") -> Jun-30 | BE3: =TEXT(EDATE(Controls!$B$6,54),"mmm-yy") -> Jul-30 | BF3: =TEXT(EDATE(Controls!$B$6,55),"mmm-yy") -> Aug-30 | BG3: =TEXT(EDATE(Controls!$B$6,56),"mmm-yy") -> Sep-30 | BH3: =TEXT(EDATE(Controls!$B$6,57),"mmm-yy") -> Oct-30 | BI3: =TEXT(EDATE(Controls!$B$6,58),"mmm-yy") -> Nov-30 | BJ3: =TEXT(EDATE(Controls!$B$6,59),"mmm-yy") -> Dec-30 | BK3: ="FY "&(YEAR(Controls!$B$6)+0) -> FY 2026 | BL3: ="FY "&(YEAR(Controls!$B$6)+1) -> FY 2027 | BM3: ="FY "&(YEAR(Controls!$B$6)+2) -> FY 2028 | BN3: ="FY "&(YEAR(Controls!$B$6)+3) -> FY 2029 | BO3: ="FY "&(YEAR(Controls!$B$6)+4) -> FY 2030 | BP3: ="FY "&(YEAR(Controls!$B$6)+5) -> FY 2031
A5: NON-WAGE OPEX · Enter Year 1 monthly amounts — Years 2 & 3 auto-grow by dept YoY rate
A6: COGS – Non-Wage
A7: YoY Growth Rate – COGS – Non-Wage | B7: %/yr | C7: 0.2 | D7: ↑ Applies to months 13–36 (rolling 12-mo from model start, not calendar year)
A8: Cloud Hosting & Infrastructure | B8: $/mo | C8: 3000 | D8: 3000 | E8: 3000 | F8: 3000 | G8: 3000 | H8: 3000 | I8: 3000 | J8: 3000 | K8: 3000 | L8: 3000 | M8: 3000 | N8: 3000 | O8: =IF(COLUMN()-2<=Controls!$B$7,C8*(1+$C$7),0) -> 3600 | P8: =IF(COLUMN()-2<=Controls!$B$7,D8*(1+$C$7),0) -> 3600 | Q8: =IF(COLUMN()-2<=Controls!$B$7,E8*(1+$C$7),0) -> 3600 | R8: =IF(COLUMN()-2<=Controls!$B$7,F8*(1+$C$7),0) -> 3600 | S8: =IF(COLUMN()-2<=Controls!$B$7,G8*(1+$C$7),0) -> 3600 | T8: =IF(COLUMN()-2<=Controls!$B$7,H8*(1+$C$7),0) -> 3600 | U8: =IF(COLUMN()-2<=Controls!$B$7,I8*(1+$C$7),0) -> 3600 | V8: =IF(COLUMN()-2<=Controls!$B$7,J8*(1+$C$7),0) -> 3600 | ... BJ8: =IF(COLUMN()-2<=Controls!$B$7,AX8*(1+$C$7),0) -> 0 | BK8: =SUMPRODUCT((YEAR(EDATE(Controls!$B$6,COLUMN($C$1:$BJ$1)-COLUMN($C$1)))=YEAR(Controls!$B$6)+0)*(COLUMN($C$1:$BJ$1)-COLUMN($C$1)<Controls!$B$7)*$C$8:$BJ$8) -> 36000 | BL8: =SUMPRODUCT((YEAR(EDATE(Controls!$B$6,COLUMN($C$1:$BJ$1)-COLUMN($C$1)))=YEAR(Controls!$B$6)+1)*(COLUMN($C$1:$BJ$1)-COLUMN($C$1)<Controls!$B$7)*$C$8:$BJ$8) -> 43200 | BM8: =SUMPRODUCT((YEAR(EDATE(Controls!$B$6,COLUMN($C$1:$BJ$1)-COLUMN($C$1)))=YEAR(Controls!$B$6)+2)*(COLUMN($C$1:$BJ$1)-COLUMN($C$1)<Controls!$B$7)*$C$8:$BJ$8) -> 51840 | BN8: =SUMPRODUCT((YEAR(EDATE(Controls!$B$6,COLUMN($C$1:$BJ$1)-COLUMN($C$1)))=YEAR(Controls!$B$6)+3)*(COLUMN($C$1:$BJ$1)-COLUMN($C$1)<Controls!$B$7)*$C$8:$BJ$8) -> 0 | BO8: =SUMPRODUCT((YEAR(EDATE(Controls!$B$6,COLUMN($C$1:$BJ$1)-COLUMN($C$1)))=YEAR(Controls!$B$6)+4)*(COLUMN($C$1:$BJ$1)-COLUMN($C$1)<Controls!$B$7)*$C$8:$BJ$8) -> 0 | BP8: =SUMPRODUCT((YEAR(EDATE(Controls!$B$6,COLUMN($C$1:$BJ$1)-COLUMN($C$1)))=YEAR(Controls!$B$6)+5)*(COLUMN($C$1:$BJ$1)-COLUMN($C$1)<Controls!$B$7)*$C$8:$BJ$8) -> 0
A9: Other COGS (Support Tools, Ops) | B9: $/mo | C9: 1000 | D9: 1000 | E9: 1000 | F9: 1000 | G9: 1000 | H9: 1000 | I9: 1000 | J9: 1000 | K9: 1000 | L9: 1000 | M9: 1000 | N9: 1000 | O9: =IF(COLUMN()-2<=Controls!$B$7,C9*(1+$C$7),0) -> 1200 | P9: =IF(COLUMN()-2<=Controls!$B$7,D9*(1+$C$7),0) -> 1200 | Q9: =IF(COLUMN()-2<=Controls!$B$7,E9*(1+$C$7),0) -> 1200 | R9: =IF(COLUMN()-2<=Controls!$B$7,F9*(1+$C$7),0) -> 1200 | S9: =IF(COLUMN()-2<=Controls!$B$7,G9*(1+$C$7),0) -> 1200 | T9: =IF(COLUMN()-2<=Controls!$B$7,H9*(1+$C$7),0) -> 1200 | U9: =IF(COLUMN()-2<=Controls!$B$7,I9*(1+$C$7),0) -> 1200 | V9: =IF(COLUMN()-2<=Controls!$B$7,J9*(1+$C$7),0) -> 1200 | ... BJ9: =IF(COLUMN()-2<=Controls!$B$7,AX9*(1+$C$7),0) -> 0 | BK9: =SUMPRODUCT((YEAR(EDATE(Controls!$B$6,COLUMN($C$1:$BJ$1)-COLUMN($C$1)))=YEAR(Controls!$B$6)+0)*(COLUMN($C$1:$BJ$1)-COLUMN($C$1)<Controls!$B$7)*$C$9:$BJ$9) -> 12000 | BL9: =SUMPRODUCT((YEAR(EDATE(Controls!$B$6,COLUMN($C$1:$BJ$1)-COLUMN($C$1)))=YEAR(Controls!$B$6)+1)*(COLUMN($C$1:$BJ$1)-COLUMN($C$1)<Controls!$B$7)*$C$9:$BJ$9) -> 14400 | BM9: =SUMPRODUCT((YEAR(EDATE(Controls!$B$6,COLUMN($C$1:$BJ$1)-COLUMN($C$1)))=YEAR(Controls!$B$6)+2)*(COLUMN($C$1:$BJ$1)-COLUMN($C$1)<Controls!$B$7)*$C$9:$BJ$9) -> 17280 | BN9: =SUMPRODUCT((YEAR(EDATE(Controls!$B$6,COLUMN($C$1:$BJ$1)-COLUMN($C$1)))=YEAR(Controls!$B$6)+3)*(COLUMN($C$1:$BJ$1)-COLUMN($C$1)<Controls!$B$7)*$C$9:$BJ$9) -> 0 | BO9: =SUMPRODUCT((YEAR(EDATE(Controls!$B$6,COLUMN($C$1:$BJ$1)-COLUMN($C$1)))=YEAR(Controls!$B$6)+4)*(COLUMN($C$1:$BJ$1)-COLUMN($C$1)<Controls!$B$7)*$C$9:$BJ$9) -> 0 | BP9: =SUMPRODUCT((YEAR(EDATE(Controls!$B$6,COLUMN($C$1:$BJ$1)-COLUMN($C$1)))=YEAR(Controls!$B$6)+5)*(COLUMN($C$1:$BJ$1)-COLUMN($C$1)<Controls!$B$7)*$C$9:$BJ$9) -> 0
A10: S&M – Non-Wage
A11: YoY Growth Rate – S&M – Non-Wage | B11: %/yr | C11: 0.35 | D11: ↑ Applies to months 13–36 (rolling 12-mo from model start, not calendar year)
A12: Digital Marketing & Advertising | B12: $/mo | C12: 8000 | D12: 8000 | E12: 8000 | F12: 8000 | G12: 8000 | H12: 8000 | I12: 8000 | J12: 8000 | K12: 8000 | L12: 8000 | M12: 8000 | N12: 8000 | O12: =IF(COLUMN()-2<=Controls!$B$7,C12*(1+$C$11),0) -> 10800 | P12: =IF(COLUMN()-2<=Controls!$B$7,D12*(1+$C$11),0) -> 10800 | Q12: =IF(COLUMN()-2<=Controls!$B$7,E12*(1+$C$11),0) -> 10800 | R12: =IF(COLUMN()-2<=Controls!$B$7,F12*(1+$C$11),0) -> 10800 | S12: =IF(COLUMN()-2<=Controls!$B$7,G12*(1+$C$11),0) -> 10800 | T12: =IF(COLUMN()-2<=Controls!$B$7,H12*(1+$C$11),0) -> 10800 | U12: =IF(COLUMN()-2<=Controls!$B$7,I12*(1+$C$11),0) -> 10800 | V12: =IF(COLUMN()-2<=Controls!$B$7,J12*(1+$C$11),0) -> 10800 | ... BJ12: =IF(COLUMN()-2<=Controls!$B$7,AX12*(1+$C$11),0) -> 0 | BK12: =SUMPRODUCT((YEAR(EDATE(Controls!$B$6,COLUMN($C$1:$BJ$1)-COLUMN($C$1)))=YEAR(Controls!$B$6)+0)*(COLUMN($C$1:$BJ$1)-COLUMN($C$1)<Controls!$B$7)*$C$12:$BJ$12) -> 96000 | BL12: =SUMPRODUCT((YEAR(EDATE(Controls!$B$6,COLUMN($C$1:$BJ$1)-COLUMN($C$1)))=YEAR(Controls!$B$6)+1)*(COLUMN($C$1:$BJ$1)-COLUMN($C$1)<Controls!$B$7)*$C$12:$BJ$12) -> 129600 | BM12: =SUMPRODUCT((YEAR(EDATE(Controls!$B$6,COLUMN($C$1:$BJ$1)-COLUMN($C$1)))=YEAR(Controls!$B$6)+2)*(COLUMN($C$1:$BJ$1)-COLUMN($C$1)<Controls!$B$7)*$C$12:$BJ$12) -> 174960 | BN12: =SUMPRODUCT((YEAR(EDATE(Controls!$B$6,COLUMN($C$1:$BJ$1)-COLUMN($C$1)))=YEAR(Controls!$B$6)+3)*(COLUMN($C$1:$BJ$1)-COLUMN($C$1)<Controls!$B$7)*$C$12:$BJ$12) -> 0 | BO12: =SUMPRODUCT((YEAR(EDATE(Controls!$B$6,COLUMN($C$1:$BJ$1)-COLUMN($C$1)))=YEAR(Controls!$B$6)+4)*(COLUMN($C$1:$BJ$1)-COLUMN($C$1)<Controls!$B$7)*$C$12:$BJ$12) -> 0 | BP12: =SUMPRODUCT((YEAR(EDATE(Controls!$B$6,COLUMN($C$1:$BJ$1)-COLUMN($C$1)))=YEAR(Controls!$B$6)+5)*(COLUMN($C$1:$BJ$1)-COLUMN($C$1)<Controls!$B$7)*$C$12:$BJ$12) -> 0
A13: Sales Tools (CRM, Outreach) | B13: $/mo | C13: 1500 | D13: 1500 | E13: 1500 | F13: 1500 | G13: 1500 | H13: 1500 | I13: 1500 | J13: 1500 | K13: 1500 | L13: 1500 | M13: 1500 | N13: 1500 | O13: =IF(COLUMN()-2<=Controls!$B$7,C13*(1+$C$11),0) -> 2025 | P13: =IF(COLUMN()-2<=Controls!$B$7,D13*(1+$C$11),0) -> 2025 | Q13: =IF(COLUMN()-2<=Controls!$B$7,E13*(1+$C$11),0) -> 2025 | R13: =IF(COLUMN()-2<=Controls!$B$7,F13*(1+$C$11),0) -> 2025 | S13: =IF(COLUMN()-2<=Controls!$B$7,G13*(1+$C$11),0) -> 2025 | T13: =IF(COLUMN()-2<=Controls!$B$7,H13*(1+$C$11),0) -> 2025 | U13: =IF(COLUMN()-2<=Controls!$B$7,I13*(1+$C$11),0) -> 2025 | V13: =IF(COLUMN()-2<=Controls!$B$7,J13*(1+$C$11),0) -> 2025 | ... BJ13: =IF(COLUMN()-2<=Controls!$B$7,AX13*(1+$C$11),0) -> 0 | BK13: =SUMPRODUCT((YEAR(EDATE(Controls!$B$6,COLUMN($C$1:$BJ$1)-COLUMN($C$1)))=YEAR(Controls!$B$6)+0)*(COLUMN($C$1:$BJ$1)-COLUMN($C$1)<Controls!$B$7)*$C$13:$BJ$13) -> 18000 | BL13: =SUMPRODUCT((YEAR(EDATE(Controls!$B$6,COLUMN($C$1:$BJ$1)-COLUMN($C$1)))=YEAR(Controls!$B$6)+1)*(COLUMN($C$1:$BJ$1)-COLUMN($C$1)<Controls!$B$7)*$C$13:$BJ$13) -> 24300 | BM13: =SUMPRODUCT((YEAR(EDATE(Controls!$B$6,COLUMN($C$1:$BJ$1)-COLUMN($C$1)))=YEAR(Controls!$B$6)+2)*(COLUMN($C$1:$BJ$1)-COLUMN($C$1)<Controls!$B$7)*$C$13:$BJ$13) -> 32805 | BN13: =SUMPRODUCT((YEAR(EDATE(Controls!$B$6,COLUMN($C$1:$BJ$1)-COLUMN($C$1)))=YEAR(Controls!$B$6)+3)*(COLUMN($C$1:$BJ$1)-COLUMN($C$1)<Controls!$B$7)*$C$13:$BJ$13) -> 0 | BO13: =SUMPRODUCT((YEAR(EDATE(Controls!$B$6,COLUMN($C$1:$BJ$1)-COLUMN($C$1)))=YEAR(Controls!$B$6)+4)*(COLUMN($C$1:$BJ$1)-COLUMN($C$1)<Controls!$B$7)*$C$13:$BJ$13) -> 0 | BP13: =SUMPRODUCT((YEAR(EDATE(Controls!$B$6,COLUMN($C$1:$BJ$1)-COLUMN($C$1)))=YEAR(Controls!$B$6)+5)*(COLUMN($C$1:$BJ$1)-COLUMN($C$1)<Controls!$B$7)*$C$13:$BJ$13) -> 0
